Workbook
Name A: #REF!
Name BaseTHF: #REF!
Name boxsections: '[1]NOT ANNEALED'!$A$11:$IV$13
Name CICCIO: '[2]NOT ANNEALED'!$A$14:$IV$14
Name extrapercTHF: #REF!
Name FissoTHF: #REF!
Name kg.mtTHF: #REF!
Name LegaTHF: #REF!
Name Misura: #REF!
Name ScontoTHF: #REF!
Name ValutaTHF: #REF!

Sheet BUSINESS
A1: N | C1: Descrizione | D1: Cod.Altern. | E1: U.M. | F1: NON A LISTINO | G1: DA LISTINI TUBO | H1: PREZZO MANUALE O EXTRA | I1: BUSINESS | J1: RIF
A2: 1 | B2: ANELLO304-KG | C2: ANELLO TAGL. DA LAM. ACC. AISI 304 | E2: KG | F2: KZ | I2: =IF(F2="KZ",0,G2+H2) -> 0
A3: 2 | B3: ANELLO304-PZ | C3: ANELLO TAGL. DA LAM. ACC. AISI 304 | E3: PZ | F3: KZ | I3: =IF(F3="KZ",0,G3+H3) -> 0
A4: 3 | B4: ANELLO316-KG | C4: ANELLO TAGL. DA LAM. ACC. AISI 316 | E4: KG | F4: KZ | I4: =IF(F4="KZ",0,G4+H4) -> 0
A5: 4 | B5: ANELLO316-PZ | C5: ANELLO TAGL. DA LAM. ACC. AISI 316 | E5: PZ | F5: KZ | I5: =IF(F5="KZ",0,G5+H5) -> 0
A6: 5 | B6: ANELLO316-PZ-SP.08 | C6: ANELLO TAGL.DA LAM.ACC. AISI 316L SP.8 | E6: PZ | F6: KZ | I6: =IF(F6="KZ",0,G6+H6) -> 0
A7: 6 | B7: ANELLO316-PZ-SP.30 | C7: ANELLO TAGL.DA LAM.ACC. AISI 316L SP.30 | E7: PZ | F7: KZ | I7: =IF(F7="KZ",0,G7+H7) -> 0
A8: 7 | B8: ANG INOX DA LAM. | C8: ANG. ACC. AISI 304 DA LAMIERA | E8: KG | F8: KZ | I8: =IF(F8="KZ",0,G8+H8) -> 0
A9: 8 | B9: ANG304 | C9: ANG. ACC. AISI 304 LAM. | E9: KG | F9: KZ | I9: =IF(F9="KZ",0,G9+H9) -> 0
A10: 9 | B10: ANG304-100X100X10 | C10: ANG. ACC. AISI 304 LAM. | D10: 100 X 100 X 10 | E10: KG | G10: =ANG!D32 -> 3.36 | I10: =IF(F10="KZ",0,G10+H10) -> 3.36
A11: 10 | B11: ANG304-20X20X3 | C11: ANG. ACC. AISI 304 LAM. | D11: 20 X 20 X 3 | E11: KG | G11: =ANG!D8 -> 3.76 | I11: =IF(F11="KZ",0,G11+H11) -> 3.76
A12: 11 | B12: ANG304-25X25X3 | C12: ANG. ACC. AISI 304 LAM. | D12: 25 X 25 X 3 | E12: KG | G12: =ANG!D10 -> 3.59 | I12: =IF(F12="KZ",0,G12+H12) -> 3.59
A13: 12 | B13: ANG304-25X25X4 | C13: ANG. ACC. AISI 304 LAM. | D13: 25 X 25 X 4 | E13: KG | G13: =ANG!D11 -> 3.59 | I13: =IF(F13="KZ",0,G13+H13) -> 3.59
A14: 13 | B14: ANG304-25X25X5 | C14: ANG. ACC. AISI 304 LAM | D14: 25 X 25 X 5 | E14: KG | G14: =ANG!D12 -> 3.59 | I14: =IF(F14="KZ",0,G14+H14) -> 3.59
A15: 14 | B15: ANG304-30X30X3 | C15: ANG. ACC. AISI 304 LAM. | D15: 30 X 30 X 3 | E15: KG | G15: =ANG!D14 -> 3.46 | I15: =IF(F15="KZ",0,G15+H15) -> 3.46
A16: 15 | B16: ANG304-30X30X4 | C16: ANG. ACC. AISI 304 LAM. | D16: 30 X 30 X 4 | E16: KG | G16: =ANG!D15 -> 3.46 | H16: 0.31 | I16: =IF(F16="KZ",0,G16+H16) -> 3.77
A17: 16 | B17: ANG304-30X30X5 | C17: ANG. ACC. AISI 304 LAM. | D17: 30 X 30 X 5 | E17: KG | G17: =ANG!D16 -> 3.36 | H17: 0.41 | I17: =IF(F17="KZ",0,G17+H17) -> 3.77
A18: 17 | B18: ANG304-35X35X3 | C18: ANG. ACC. AISI 304 LAM | D18: 35 X 35 X 3 | E18: KG | F18: KZ | G18: =ANG!B18 -> 3 | H18: 0.4 | I18: =IF(F18="KZ",0,G18+H18) -> 0
A19: 18 | B19: ANG304-35X35X4 | C19: ANG. ACC. AISI 304 LAM. | D19: 35 X 35 X 4 | E19: KG | G19: =ANG!D19 -> 3.36 | I19: =IF(F19="KZ",0,G19+H19) -> 3.36
A20: 19 | B20: ANG304-40X40X3 | C20: ANG. ACC. AISI 304 LAM. | D20: 40 X 40 X 3 | E20: KG | G20: =ANG!D21 -> 3.36 | I20: =IF(F20="KZ",0,G20+H20) -> 3.36
A21: 20 | B21: ANG304-40X40X4,0 | C21: ANG. ACC. AISI 304 LAM. | D21: 40 X 40 X 4 | E21: KG | G21: =ANG!D22 -> 3.36 | I21: =IF(F21="KZ",0,G21+H21) -> 3.36
A22: 21 | B22: ANG304-40X40X5 | C22: ANG. ACC. AISI 304 LAM. | D22: 40 X 40 X 5 | E22: KG | G22: =ANG!D23 -> 3.36 | H22: 0.11 | I22: =IF(F22="KZ",0,G22+H22) -> 3.47
A23: 22 | B23: ANG304-40X40X6 | C23: ANG. ACC. AISI 304 LAM. | D23: 40 X 40 X 6 | E23: KG | F23: KZ | I23: =IF(F23="KZ",0,G23+H23) -> 0
B24: ANG304-50X50X4 | C24: ANG. ACC. AISI 304 LAM. | D24: 50 X 50 X 4 | E24: KG | F24: KZ | G24: =ANG!D25 -> 3.36 | I24: =IF(F24="KZ",0,G24+H24) -> 0
A25: 23 | B25: ANG304-50X50X5 | C25: ANG. ACC. AISI 304 LAM. | D25: 50 X 50 X 5 | E25: KG | G25: =ANG!D26 -> 3.36 | I25: =IF(F25="KZ",0,G25+H25) -> 3.36
A26: 24 | B26: ANG304-60X60X6 | C26: ANG. ACC. AISI 304 LAM. | D26: 60 X 60 X 6 | E26: KG | G26: =ANG!D28 -> 3.36 | I26: =IF(F26="KZ",0,G26+H26) -> 3.36
A27: 25 | B27: ANG304-70X70X7 | C27: ANG. ACC. AISI 304 LAM. | D27: 70 X 70 X 7 | E27: KG | F27: KZ | I27: =IF(F27="KZ",0,G27+H27) -> 0
A28: 26 | B28: ANG304-80X80X8 | C28: ANG. ACC. AISI 304 LAM. | D28: 80 X 80 X 8 | E28: KG | G28: =ANG!D30 -> 3.36 | I28: =IF(F28="KZ",0,G28+H28) -> 3.36
A29: 27 | B29: ANG310 | C29: ANG. ACC. AISI 310 LAM. | E29: KG | F29: KZ | I29: =IF(F29="KZ",0,G29+H29) -> 0
A30: 28 | B30: ANG316 | C30: ANG. ACC. AISI 316 LAM. | E30: KG | F30: KZ | I30: =IF(F30="KZ",0,G30+H30) -> 0
A31: 29 | B31: ANG316-020X20X3 | C31: ANG. ACC. AISI 316 LAM. | D31: 20 X 20 X 3 | E31: KG | F31: KZ | G31: =ANG!H8 -> 0 | I31: =IF(F31="KZ",0,G31+H31) -> 0
A32: 30 | B32: ANG316-025X25X3 | C32: ANG. ACC. AISI 316 LAM. | D32: 25 X 25 X 3 | E32: KG | F32: KZ | G32: =ANG!H10 -> 0 | I32: =IF(F32="KZ",0,G32+H32) -> 0
A33: 31 | B33: ANG316-030X30X3 | C33: ANG. ACC. AISI 316 LAM. | D33: 30 X 30 X 3 | E33: KG | F33: KZ | G33: =ANG!H14 -> 0 | I33: =IF(F33="KZ",0,G33+H33) -> 0
A34: 32 | B34: ANG316-030X30X4 | C34: ANG. ACC. AISI 316 LAM. | D34: 30 X 30 X 4 | E34: KG | F34: KZ | G34: =ANG!H15 -> 0 | I34: =IF(F34="KZ",0,G34+H34) -> 0
A35: 33 | B35: ANG316-035X35X4,0 | C35: ANG. ACC. AISI 316 LAM. | D35: 35 X 35 X 4 | E35: KG | F35: KZ | G35: =ANG!H19 -> 0 | I35: =IF(F35="KZ",0,G35+H35) -> 0
A36: 34 | B36: ANG316-040X40X4,0 | C36: ANG. ACC. AISI 316 LAM. | D36: 40 X 40 X 4 | E36: KG | F36: KZ | G36: =ANG!H22 -> 0 | I36: =IF(F36="KZ",0,G36+H36) -> 0
A37: 35 | B37: ANG316-040X40X5,0 | C37: ANG. ACC. AISI 316 LAM. | D37: 40 X 40 X 5 | E37: KG | F37: KZ | G37: =ANG!H23 -> 0 | I37: =IF(F37="KZ",0,G37+H37) -> 0
A38: 36 | B38: ANG316-50X50X5 | C38: ANG. ACC. AISI 316 LAM. | D38: 50 X 50 X 5 | E38: KG | F38: KZ | G38: =ANG!H26 -> 6.05 | I38: =IF(F38="KZ",0,G38+H38) -> 0
A39: 37 | B39: ANG316-60X60X6 | C39: ANG. ACC. AISI 316 LAM. | D39: 60 X 60 X 6 | E39: KG | F39: KZ | G39: =ANG!H28 -> 6.05 | I39: =IF(F39="KZ",0,G39+H39) -> 0
A40: 38 | B40: ANG316-75X75X10 | C40: ANG. ACC. AISI 316 LAM. | D40: 75 X 75 X 10 | E40: KG | F40: KZ | I40: =IF(F40="KZ",0,G40+H40) -> 0
...

Sheet ROUND HF
A1: PRICE LIST MAY '26 | T1: DC 8.2_03
C2: DISCOUNT | M2: 0.52 | N2: 0.52
C3: Alloy Surcharge €/Kg | M3: 0 | N3: 0
C4: ROUND HF | M4: 304L | N4: 316L | V4: DKK | W4: 0
V5: EUR | W5: 1
V6: GBP | W6: 0.87
D7: EXTRA % | M7: 1 | V7: NOK | W7: 0
C8: Rate | M8: EUR | V8: SEK | W8: 0
V9: USD | W9: 1.16
M10: BRUSHED NOT ANNEALED | P10: O.D. POLISHED G.240/320 | S10: O.D. MIRROR POLISHED
B11: MT | C11: Dimension | F11: €/kg | M11: 1.4301 | N11: 1.4404 1.4571 | P11: 1.4301 | Q11: 1.4404 1.4571 | S11: 1.4301 | T11: 1.4404 1.4571 | V11: IN USO | W11: =VLOOKUP(M8,$V$4:$W$9,2) -> 1
B12: PACCO | C12: diam. | D12: Thk. | E12: kg/mt | F12: €/kg | H12: 304 | I12: ex 316 | J12: b 316 | K12: 316L | M12: 304 | N12: 316 J / Ti | O12: SAT | P12: 304 | Q12: 316 L / Ti | R12: LUC | S12: 304 | T12: 316 L / Ti | U12: Kg/Bdl
B13: 810 | C13: 12 | D13: 1 | E13: =(C13-D13)*D13*0.02504 -> 0.27544 | F13: 1 | G13: =CONCATENATE(C13,D13) -> 121 | H13: 2.85 | I13: 1.2 | J13: 3.65 | K13: =I13+J13 -> 4.85 | M13: =((F13*(1-$M$2)+H13+$M$3)*E13*$M$7)*$W$11 -> 0.9172152 | O13: 0.68904 | P13: =M13+O13*$W$11 -> 1.6062552 | R13: 1.2474 | S13: =M13+R13*$W$11 -> 2.1646152 | U13: =E13*B13 -> 223.1064
B14: 810 | C14: 12 | D14: 1.2 | E14: =(C14-D14)*D14*0.02504 -> 0.3245184 | F14: 1 | G14: =CONCATENATE(C14,D14) -> 121,2 | H14: 2.9 | I14: 1.2 | J14: 3.7 | K14: =I14+J14 -> 4.9 | M14: =((F14*(1-$M$2)+H14+$M$3)*E14*$M$7)*$W$11 -> 1.0968722 | O14: 0.69 | P14: =M14+O14*$W$11 -> 1.7868722 | R14: 1.2474 | S14: =M14+R14*$W$11 -> 2.3442722 | U14: =E14*B14 -> 262.8599
B15: 810 | C15: 12 | D15: 1.5 | E15: =(C15-D15)*D15*0.02504 -> 0.39438 | F15: 1 | G15: =CONCATENATE(C15,D15) -> 121,5 | H15: 2.77 | I15: 1.2 | J15: 3.57 | K15: =I15+J15 -> 4.77 | M15: =((F15*(1-$M$2)+H15+$M$3)*E15*$M$7)*$W$11 -> 1.281735 | N15: =((F15*(1-$N$2)+K15+$N$3)*E15*$M$7)*$W$11 -> 2.070495 | O15: 0.68904 | P15: =M15+O15*$W$11 -> 1.970775 | Q15: =N15+O15*$W$11 -> 2.759535 | R15: 1.2474 | S15: =M15+R15*$W$11 -> 2.529135 | T15: =N15+R15*$W$11 -> 3.317895 | U15: =E15*B15 -> 319.4478
B16: 678 | C16: 14 | D16: 1 | E16: =(C16-D16)*D16*0.02504 -> 0.32552 | F16: 1 | G16: =CONCATENATE(C16,D16) -> 141 | H16: 2.76 | I16: 1.2 | J16: 3.56 | K16: =I16+J16 -> 4.76 | M16: =((F16*(1-$M$2)+H16+$M$3)*E16*$M$7)*$W$11 -> 1.0546848 | O16: 0.68904 | P16: =M16+O16*$W$11 -> 1.7437248 | R16: 1.2474 | S16: =M16+R16*$W$11 -> 2.3020848 | U16: =E16*B16 -> 220.70256
B17: 679 | C17: 14 | D17: 1.2 | E17: =(C17-D17)*D17*0.02504 -> 0.3846144 | F17: 1 | G17: =CONCATENATE(C17,D17) -> 141,2 | H17: 2.8 | I17: 1.2 | J17: 3.6 | K17: =I17+J17 -> 4.8 | M17: =((F17*(1-$M$2)+H17+$M$3)*E17*$M$7)*$W$11 -> 1.2615352 | O17: 0.69 | P17: =M17+O17*$W$11 -> 1.9515352 | R17: 1.25 | S17: =M17+R17*$W$11 -> 2.5115352 | U17: =E17*B17 -> 261.15318
B18: 678 | C18: 14 | D18: 1.5 | E18: =(C18-D18)*D18*0.02504 -> 0.4695 | F18: 1 | G18: =CONCATENATE(C18,D18) -> 141,5 | H18: 2.7 | I18: 1.2 | J18: 3.5 | K18: =I18+J18 -> 4.7 | M18: =((F18*(1-$M$2)+H18+$M$3)*E18*$M$7)*$W$11 -> 1.49301 | N18: =((F18*(1-$N$2)+K18+$N$3)*E18*$M$7)*$W$11 -> 2.43201 | O18: 0.68904 | P18: =M18+O18*$W$11 -> 2.18205 | Q18: =N18+O18*$W$11 -> 3.12105 | R18: 1.2474 | S18: =M18+R18*$W$11 -> 2.74041 | T18: =N18+R18*$W$11 -> 3.67941 | U18: =E18*B18 -> 318.321
B19: 678 | C19: 14 | D19: 2 | E19: =(C19-D19)*D19*0.02504 -> 0.60096 | F19: 1 | G19: =CONCATENATE(C19,D19) -> 142 | H19: 2.43 | I19: 1.47 | J19: 3.08 | K19: =I19+J19 -> 4.55 | M19: =((F19*(1-$M$2)+H19+$M$3)*E19*$M$7)*$W$11 -> 1.7487936 | N19: =((F19*(1-$N$2)+K19+$N$3)*E19*$M$7)*$W$11 -> 3.0228288 | O19: 0.7128 | P19: =M19+O19*$W$11 -> 2.4615936 | Q19: =N19+O19*$W$11 -> 3.7356288 | R19: 1.2474 | S19: =M19+R19*$W$11 -> 2.9961936 | T19: =N19+R19*$W$11 -> 4.2702288 | U19: =E19*B19 -> 407.45088
B20: 678 | C20: 15 | D20: 1 | E20: =(C20-D20)*D20*0.02504 -> 0.35056 | F20: 1 | G20: =CONCATENATE(C20,D20) -> 151 | H20: 2.75 | I20: 1.2 | J20: 3.55 | K20: =I20+J20 -> 4.75 | M20: =((F20*(1-$M$2)+H20+$M$3)*E20*$M$7)*$W$11 -> 1.1323088 | O20: 0.68904 | P20: =M20+O20*$W$11 -> 1.8213488 | R20: 1.2474 | S20: =M20+R20*$W$11 -> 2.3797088 | U20: =E20*B20 -> 237.67968
B21: 678 | C21: 15 | D21: 1.5 | E21: =(C21-D21)*D21*0.02504 -> 0.50706 | F21: 1 | G21: =CONCATENATE(C21,D21) -> 151,5 | H21: 2.67 | I21: 1.2 | J21: 3.47 | K21: =I21+J21 -> 4.67 | M21: =((F21*(1-$M$2)+H21+$M$3)*E21*$M$7)*$W$11 -> 1.597239 | N21: =((F21*(1-$N$2)+K21+$N$3)*E21*$M$7)*$W$11 -> 2.611359 | O21: 0.68904 | P21: =M21+O21*$W$11 -> 2.286279 | Q21: =N21+O21*$W$11 -> 3.300399 | R21: 1.2474 | S21: =M21+R21*$W$11 -> 2.844639 | T21: =N21+R21*$W$11 -> 3.858759 | U21: =E21*B21 -> 343.78668
B22: 678 | C22: 15 | D22: 2 | E22: =(C22-D22)*D22*0.02504 -> 0.65104 | F22: 1 | G22: =CONCATENATE(C22,D22) -> 152 | H22: 2.41 | I22: 1.47 | J22: 3.06 | K22: =I22+J22 -> 4.53 | M22: =((F22*(1-$M$2)+H22+$M$3)*E22*$M$7)*$W$11 -> 1.8815056 | N22: =((F22*(1-$N$2)+K22+$N$3)*E22*$M$7)*$W$11 -> 3.2617104 | O22: 0.7128 | P22: =M22+O22*$W$11 -> 2.5943056 | Q22: =N22+O22*$W$11 -> 3.9745104 | R22: 1.2474 | S22: =M22+R22*$W$11 -> 3.1289056 | T22: =N22+R22*$W$11 -> 4.5091104 | U22: =E22*B22 -> 441.40512
B23: 678 | C23: 16 | D23: 1 | E23: =(C23-D23)*D23*0.02504 -> 0.3756 | F23: 1 | G23: =CONCATENATE(C23,D23) -> 161 | H23: 2.72 | I23: 1.2 | J23: 3.52 | K23: =I23+J23 -> 4.72 | M23: =((F23*(1-$M$2)+H23+$M$3)*E23*$M$7)*$W$11 -> 1.20192 | O23: 0.68904 | P23: =M23+O23*$W$11 -> 1.89096 | R23: 1.2474 | S23: =M23+R23*$W$11 -> 2.44932 | U23: =E23*B23 -> 254.6568
B24: 678 | C24: 16 | D24: 1.2 | E24: =(C24-D24)*D24*0.02504 -> 0.4447104 | F24: 1 | G24: =CONCATENATE(C24,D24) -> 161,2 | H24: 2.7 | I24: 1.2 | J24: 3.5 | K24: =I24+J24 -> 4.7 | M24: =((F24*(1-$M$2)+H24+$M$3)*E24*$M$7)*$W$11 -> 1.4141791 | O24: 0.68904 | P24: =M24+O24*$W$11 -> 2.1032191 | R24: 1.2474 | S24: =M24+R24*$W$11 -> 2.6615791 | U24: =E24*B24 -> 301.51365
B25: 678 | C25: 16 | D25: 1.5 | E25: =(C25-D25)*D25*0.02504 -> 0.54462 | F25: 1 | G25: =CONCATENATE(C25,D25) -> 161,5 | H25: 2.64 | I25: 1.2 | J25: 3.44 | K25: =I25+J25 -> 4.64 | M25: =((F25*(1-$M$2)+H25+$M$3)*E25*$M$7)*$W$11 -> 1.6992144 | N25: =((F25*(1-$N$2)+K25+$N$3)*E25*$M$7)*$W$11 -> 2.7884544 | O25: 0.68904 | P25: =M25+O25*$W$11 -> 2.3882544 | Q25: =N25+O25*$W$11 -> 3.4774944 | R25: 1.2474 | S25: =M25+R25*$W$11 -> 2.9466144 | T25: =N25+R25*$W$11 -> 4.0358544 | U25: =E25*B25 -> 369.25236
B26: 678 | C26: 16 | D26: 2 | E26: =(C26-D26)*D26*0.02504 -> 0.70112 | F26: 1 | G26: =CONCATENATE(C26,D26) -> 162 | H26: 2.38 | I26: 1.47 | J26: 3.03 | K26: =I26+J26 -> 4.5 | M26: =((F26*(1-$M$2)+H26+$M$3)*E26*$M$7)*$W$11 -> 2.0052032 | N26: =((F26*(1-$N$2)+K26+$N$3)*E26*$M$7)*$W$11 -> 3.4915776 | O26: 0.7128 | P26: =M26+O26*$W$11 -> 2.7180032 | Q26: =N26+O26*$W$11 -> 4.2043776 | R26: 1.2474 | S26: =M26+R26*$W$11 -> 3.2526032 | T26: =N26+R26*$W$11 -> 4.7389776 | U26: =E26*B26 -> 475.35936
A27: 3/8" | B27: 678 | C27: 17.2 | D27: 1.5 | E27: =(C27-D27)*D27*0.02504 -> 0.589692 | F27: 1 | G27: =CONCATENATE(C27,D27) -> 17,21,5 | H27: 2.59 | I27: 1.2 | J27: 3.39 | K27: =I27+J27 -> 4.59 | M27: =((F27*(1-$M$2)+H27+$M$3)*E27*$M$7)*$W$11 -> 1.8103544 | N27: =((F27*(1-$N$2)+K27+$N$3)*E27*$M$7)*$W$11 -> 2.9897384 | O27: 0.68904 | P27: =M27+O27*$W$11 -> 2.4993944 | Q27: =N27+O27*$W$11 -> 3.6787784 | R27: 1.2474 | S27: =M27+R27*$W$11 -> 3.0577544 | T27: =N27+R27*$W$11 -> 4.2371384 | U27: =E27*B27 -> 399.81118
B28: 678 | C28: 17.2 | D28: 2 | E28: =(C28-D28)*D28*0.02504 -> 0.761216 | F28: 1 | G28: =CONCATENATE(C28,D28) -> 17,22 | H28: 2.32 | I28: 1.47 | J28: 2.97 | K28: =I28+J28 -> 4.44 | M28: =((F28*(1-$M$2)+H28+$M$3)*E28*$M$7)*$W$11 -> 2.1314048 | N28: =((F28*(1-$N$2)+K28+$N$3)*E28*$M$7)*$W$11 -> 3.7451827 | O28: 0.7128 | P28: =M28+O28*$W$11 -> 2.8442048 | Q28: =N28+O28*$W$11 -> 4.4579827 | R28: 1.2474 | S28: =M28+R28*$W$11 -> 3.3788048 | T28: =N28+R28*$W$11 -> 4.9925827 | U28: =E28*B28 -> 516.10445
B29: 678 | C29: 17.2 | D29: 2.5 | E29: =(C29-D29)*D29*0.02504 -> 0.92022 | F29: 1 | G29: =CONCATENATE(C29,D29) -> 17,22,5 | H29: 2.4 | I29: 1.3 | J29: 3.2 | K29: =I29+J29 -> 4.5 | M29: =((F29*(1-$M$2)+H29+$M$3)*E29*$M$7)*$W$11 -> 2.6502336 | N29: =((F29*(1-$N$2)+K29+$N$3)*E29*$M$7)*$W$11 -> 4.5826956 | O29: 0.71 | P29: =M29+O29*$W$11 -> 3.3602336 | Q29: =N29+O29*$W$11 -> 5.2926956 | R29: 1.79 | S29: =M29+R29*$W$11 -> 4.4402336 | T29: =N29+R29*$W$11 -> 6.3726956 | U29: =E29*B29 -> 623.90916
B30: 678 | C30: 18 | D30: 1 | E30: =(C30-D30)*D30*0.02504 -> 0.42568 | F30: 1 | G30: =CONCATENATE(C30,D30) -> 181 | H30: 2.66 | I30: 1.2 | J30: 3.46 | K30: =I30+J30 -> 4.66 | M30: =((F30*(1-$M$2)+H30+$M$3)*E30*$M$7)*$W$11 -> 1.3366352 | O30: 0.68904 | P30: =M30+O30*$W$11 -> 2.0256752 | R30: 1.2474 | S30: =M30+R30*$W$11 -> 2.5840352 | U30: =E30*B30 -> 288.61104
B31: 678 | C31: 18 | D31: 1.2 | E31: =(C31-D31)*D31*0.02504 -> 0.5048064 | F31: 1 | G31: =CONCATENATE(C31,D31) -> 181,2 | H31: 2.63 | I31: 1.2 | J31: 3.43 | K31: =I31+J31 -> 4.63 | M31: =((F31*(1-$M$2)+H31+$M$3)*E31*$M$7)*$W$11 -> 1.5699479 | O31: 0.68904 | P31: =M31+O31*$W$11 -> 2.2589879 | R31: 1.2474 | S31: =M31+R31*$W$11 -> 2.8173479 | U31: =E31*B31 -> 342.25874
B32: 678 | C32: 18 | D32: 1.5 | E32: =(C32-D32)*D32*0.02504 -> 0.61974 | F32: 1 | G32: =CONCATENATE(C32,D32) -> 181,5 | H32: 2.58 | I32: 1.2 | J32: 3.38 | K32: =I32+J32 -> 4.58 | M32: =((F32*(1-$M$2)+H32+$M$3)*E32*$M$7)*$W$11 -> 1.8964044 | N32: =((F32*(1-$N$2)+K32+$N$3)*E32*$M$7)*$W$11 -> 3.1358844 | O32: 0.68904 | P32: =M32+O32*$W$11 -> 2.5854444 | Q32: =N32+O32*$W$11 -> 3.8249244 | R32: 1.2474 | S32: =M32+R32*$W$11 -> 3.1438044 | T32: =N32+R32*$W$11 -> 4.3832844 | U32: =E32*B32 -> 420.18372
B33: 678 | C33: 18 | D33: 2 | E33: =(C33-D33)*D33*0.02504 -> 0.80128 | F33: 1 | G33: =CONCATENATE(C33,D33) -> 182 | H33: 2.31 | I33: 1.47 | J33: 2.96 | K33: =I33+J33 -> 4.43 | M33: =((F33*(1-$M$2)+H33+$M$3)*E33*$M$7)*$W$11 -> 2.2355712 | N33: =((F33*(1-$N$2)+K33+$N$3)*E33*$M$7)*$W$11 -> 3.9342848 | O33: 0.7128 | P33: =M33+O33*$W$11 -> 2.9483712 | Q33: =N33+O33*$W$11 -> 4.6470848 | R33: 1.2474 | S33: =M33+R33*$W$11 -> 3.4829712 | T33: =N33+R33*$W$11 -> 5.1816848 | U33: =E33*B33 -> 543.26784
B34: 678 | C34: 19 | D34: 1 | E34: =(C34-D34)*D34*0.02504 -> 0.45072 | F34: 1 | G34: =CONCATENATE(C34,D34) -> 191 | H34: 2.66 | I34: 1.2 | J34: 3.46 | K34: =I34+J34 -> 4.66 | M34: =((F34*(1-$M$2)+H34+$M$3)*E34*$M$7)*$W$11 -> 1.4152608 | O34: 0.68904 | P34: =M34+O34*$W$11 -> 2.1043008 | R34: 1.2474 | S34: =M34+R34*$W$11 -> 2.6626608 | U34: =E34*B34 -> 305.58816
B35: 678 | C35: 19 | D35: 1.2 | E35: =(C35-D35)*D35*0.02504 -> 0.5348544 | F35: 1 | G35: =CONCATENATE(C35,D35) -> 191,2 | H35: 2.63 | I35: 1.2 | J35: 3.43 | K35: =I35+J35 -> 4.63 | M35: =((F35*(1-$M$2)+H35+$M$3)*E35*$M$7)*$W$11 -> 1.6633972 | O35: 0.68904 | P35: =M35+O35*$W$11 -> 2.3524372 | R35: 1.2474 | S35: =M35+R35*$W$11 -> 2.9107972 | U35: =E35*B35 -> 362.63128
B36: 678 | C36: 19 | D36: 1.5 | E36: =(C36-D36)*D36*0.02504 -> 0.6573 | F36: 1 | G36: =CONCATENATE(C36,D36) -> 191,5 | H36: 2.58 | I36: 1.2 | J36: 3.38 | K36: =I36+J36 -> 4.58 | M36: =((F36*(1-$M$2)+H36+$M$3)*E36*$M$7)*$W$11 -> 2.011338 | N36: =((F36*(1-$N$2)+K36+$N$3)*E36*$M$7)*$W$11 -> 3.325938 | O36: 0.68904 | P36: =M36+O36*$W$11 -> 2.700378 | Q36: =N36+O36*$W$11 -> 4.014978 | R36: 1.2474 | S36: =M36+R36*$W$11 -> 3.258738 | T36: =N36+R36*$W$11 -> 4.573338 | U36: =E36*B36 -> 445.6494
B37: 678 | C37: 20 | D37: 1 | E37: =(C37-D37)*D37*0.02504 -> 0.47576 | F37: 1 | G37: =CONCATENATE(C37,D37) -> 201 | H37: 2.63 | I37: 1.2 | J37: 3.43 | K37: =I37+J37 -> 4.63 | M37: =((F37*(1-$M$2)+H37+$M$3)*E37*$M$7)*$W$11 -> 1.4796136 | O37: 0.68904 | P37: =M37+O37*$W$11 -> 2.1686536 | R37: 1.2474 | S37: =M37+R37*$W$11 -> 2.7270136 | U37: =E37*B37 -> 322.56528
B38: 678 | C38: 20 | D38: 1.2 | E38: =(C38-D38)*D38*0.02504 -> 0.5649024 | F38: 1 | G38: =CONCATENATE(C38,D38) -> 201,2 | H38: 2.61 | I38: 1.2 | J38: 3.41 | K38: =I38+J38 -> 4.61 | M38: =((F38*(1-$M$2)+H38+$M$3)*E38*$M$7)*$W$11 -> 1.7455484 | O38: 0.68904 | P38: =M38+O38*$W$11 -> 2.4345884 | R38: 1.2474 | S38: =M38+R38*$W$11 -> 2.9929484 | U38: =E38*B38 -> 383.00383
B39: 678 | C39: 20 | D39: 1.5 | E39: =(C39-D39)*D39*0.02504 -> 0.69486 | F39: 1 | G39: =CONCATENATE(C39,D39) -> 201,5 | H39: 2.56 | I39: 1.2 | J39: 3.36 | K39: =I39+J39 -> 4.56 | M39: =((F39*(1-$M$2)+H39+$M$3)*E39*$M$7)*$W$11 -> 2.1123744 | N39: =((F39*(1-$N$2)+K39+$N$3)*E39*$M$7)*$W$11 -> 3.5020944 | O39: 0.68904 | P39: =M39+O39*$W$11 -> 2.8014144 | Q39: =N39+O39*$W$11 -> 4.1911344 | R39: 1.2474 | S39: =M39+R39*$W$11 -> 3.3597744 | T39: =N39+R39*$W$11 -> 4.7494944 | U39: =E39*B39 -> 471.11508
B40: 678 | C40: 20 | D40: 2 | E40: =(C40-D40)*D40*0.02504 -> 0.90144 | F40: 1 | G40: =CONCATENATE(C40,D40) -> 202 | H40: 2.29 | I40: 1.47 | J40: 2.94 | K40: =I40+J40 -> 4.41 | M40: =((F40*(1-$M$2)+H40+$M$3)*E40*$M$7)*$W$11 -> 2.4969888 | N40: =((F40*(1-$N$2)+K40+$N$3)*E40*$M$7)*$W$11 -> 4.4080416 | O40: 0.7128 | P40: =M40+O40*$W$11 -> 3.2097888 | Q40: =N40+O40*$W$11 -> 5.1208416 | R40: 1.2474 | S40: =M40+R40*$W$11 -> 3.7443888 | T40: =N40+R40*$W$11 -> 5.6554416 | U40: =E40*B40 -> 611.17632
...

Sheet BOX SECTION
A1: PRICE LIST MAY '26 | X1: DC 8.2_03
B2: DISCOUNT | S2: 0.52 | T2: 304L | V2: 0.52 | W2: 316L | Y2: 0.5 | Z2: 316Ti | AC2: DKK | AD2: 0
B3: Alloy Surcharge €/Kg | S3: 0 | T3: 304L | V3: 0 | W3: 316L | Y3: 0 | Z3: 316Ti | AC3: EUR | AD3: 1
AC4: GBP | AD4: 0.87
AC5: NOK | AD5: 0
D6: EXTRA % | S6: 1 | V6: 1 | AC6: SEK | AD6: 0
D7: Rate | S7: EUR | AC7: USD | AD7: 1.16
A9: MT BDL | B9: Section | J9: EUR/KG 304 | P9: EXTRA | Q9: EXTRA | S9: 304L | T9: 304L | U9: 304L | V9: 316L | W9: 316L | X9: 316L | Y9: 316Ti | Z9: 316Ti | AA9: 316Ti | AD9: =VLOOKUP(S7,$AC$2:$AD$7,2) -> 1
B10: A | D10: B | F10: Thk. | G10: kg/mt | H10: €/kg | J10: 304 | K10: EX 316 | L10: Fisso 316L | M10: T.316L | N10: EX Ti | O10: Fis. 316Ti | P10: SATINATURA | Q10: LUCIDAT. | S10: BRUSHED | T10: POLISHED | U10: MIRROR | V10: BRUSHED | W10: POLISHED | X10: MIRROR | Y10: BRUSHED | Z10: POLISHED | AA10: MIRROR | AB10: Kg/Bdl
A11: 900 | B11: 10 | C11: x | D11: 10 | E11: x | F11: 1 | G11: =(((B11*2+D11*2)/3.14)-F11)*F11*0.02504 -> 0.29394089 | H11: 1 | I11: =CONCATENATE(B11,D11,F11) -> 10101 | J11: 3.11 | K11: 1.2 | L11: 3.91 | M11: =K11+L11 -> 5.11 | N11: 0.4 | O11: =M11+N11 -> 5.51 | P11: 1.12 | Q11: 1.81 | S11: =((H11*(1-$S$2)+J11+$S$3)*G11*$S$6)*$AD$9 -> 1.0552478 | T11: =S11+(P11*$AD$9) -> 2.1752478 | U11: =S11+(Q11*$AD$9) -> 2.8652478 | AB11: =A11*G11 -> 264.5468
A12: 900 | B12: 12 | C12: x | D12: 12 | E12: x | F12: 1 | G12: =(((B12*2+D12*2)/3.14)-F12)*F12*0.02504 -> 0.35773707 | H12: 1 | I12: =CONCATENATE(B12,D12,F12) -> 12121 | J12: 3.11 | K12: 1.5 | L12: 3.91 | M12: =K12+L12 -> 5.41 | N12: 0.4 | O12: =M12+N12 -> 5.81 | P12: 1.12 | Q12: 1.81 | S12: =((H12*(1-$S$2)+J12+$S$3)*G12*$S$6)*$AD$9 -> 1.2842761 | T12: =S12+(P12*$AD$9) -> 2.4042761 | U12: =S12+(Q12*$AD$9) -> 3.0942761 | AB12: =A12*G12 -> 321.96336
A13: 900 | B13: 12 | C13: x | D13: 12 | E13: x | F13: 1.2 | G13: =(((B13*2+D13*2)/3.14)-F13)*F13*0.02504 -> 0.42327488 | H13: 1 | I13: =CONCATENATE(B13,D13,F13) -> 12121,2 | J13: 3.03 | K13: 1.2 | L13: 3.83 | M13: =K13+L13 -> 5.03 | N13: 0.4 | O13: =M13+N13 -> 5.43 | P13: 1.12 | Q13: 1.81 | S13: =((H13*(1-$S$2)+J13+$S$3)*G13*$S$6)*$AD$9 -> 1.4856948 | T13: =S13+(P13*$AD$9) -> 2.6056948 | U13: =S13+(Q13*$AD$9) -> 3.2956948 | AB13: =A13*G13 -> 380.9474
A14: 900 | B14: 12 | C14: x | D14: 12 | E14: x | F14: 1.5 | G14: =(((B14*2+D14*2)/3.14)-F14)*F14*0.02504 -> 0.51782561 | H14: 1 | I14: =CONCATENATE(B14,D14,F14) -> 12121,5 | J14: 2.98 | K14: 1.2 | L14: 3.78 | M14: =K14+L14 -> 4.98 | N14: 0.4 | O14: =M14+N14 -> 5.38 | P14: 1.12 | Q14: 1.81 | S14: =((H14*(1-$S$2)+J14+$S$3)*G14*$S$6)*$AD$9 -> 1.7916766 | T14: =S14+(P14*$AD$9) -> 2.9116766 | U14: =S14+(Q14*$AD$9) -> 3.6016766 | V14: =((H14*(1-$V$2)+M14+$V$3)*G14*$S$6)*$AD$9 -> 2.8273278 | AB14: =A14*G14 -> 466.04304
A15: 726 | B15: 15 | C15: x | D15: 15 | E15: x | F15: 1 | G15: =(((B15*2+D15*2)/3.14)-F15)*F15*0.02504 -> 0.45343134 | H15: 1 | I15: =CONCATENATE(B15,D15,F15) -> 15151 | J15: 2.78 | K15: 1.2 | L15: 3.58 | M15: =K15+L15 -> 4.78 | N15: 0.4 | O15: =M15+N15 -> 5.18 | P15: 1.11672 | Q15: 1.80576 | S15: =((H15*(1-$S$2)+J15+$S$3)*G15*$S$6)*$AD$9 -> 1.4781862 | T15: =S15+(P15*$AD$9) -> 2.5949062 | U15: =S15+(Q15*$AD$9) -> 3.2839462 | AB15: =A15*G15 -> 329.19115
A16: 726 | B16: 15 | C16: x | D16: 15 | E16: x | F16: 1.2 | G16: =(((B16*2+D16*2)/3.14)-F16)*F16*0.02504 -> 0.53810801 | H16: 1 | I16: =CONCATENATE(B16,D16,F16) -> 15151,2 | J16: 2.76 | K16: 1.2 | L16: 3.56 | M16: =K16+L16 -> 4.76 | N16: 0.4 | O16: =M16+N16 -> 5.16 | P16: 1.11672 | Q16: 1.80576 | S16: =((H16*(1-$S$2)+J16+$S$3)*G16*$S$6)*$AD$9 -> 1.7434699 | T16: =S16+(P16*$AD$9) -> 2.8601899 | U16: =S16+(Q16*$AD$9) -> 3.5492299 | AB16: =A16*G16 -> 390.66641
A17: 726 | B17: 15 | C17: x | D17: 15 | E17: x | F17: 1.5 | G17: =(((B17*2+D17*2)/3.14)-F17)*F17*0.02504 -> 0.66136701 | H17: 1 | I17: =CONCATENATE(B17,D17,F17) -> 15151,5 | J17: 2.7 | K17: 1.2 | L17: 3.5 | M17: =K17+L17 -> 4.7 | N17: 0.4 | O17: =M17+N17 -> 5.1 | P17: 1.11672 | Q17: 1.80576 | S17: =((H17*(1-$S$2)+J17+$S$3)*G17*$S$6)*$AD$9 -> 2.1031471 | T17: =S17+(P17*$AD$9) -> 3.2198671 | U17: =S17+(Q17*$AD$9) -> 3.9089071 | V17: =((H17*(1-$V$2)+M17+$V$3)*G17*$S$6)*$AD$9 -> 3.4258811 | W17: =V17+P17*$AD$9 -> 4.5426011 | X17: =V17+(Q17*$AD$9) -> 5.2316411 | AB17: =A17*G17 -> 480.15245
A18: 726 | B18: 15 | C18: x | D18: 15 | E18: x | F18: 2 | G18: =(((B18*2+D18*2)/3.14)-F18)*F18*0.02504 -> 0.85678268 | H18: 1 | I18: =CONCATENATE(B18,D18,F18) -> 15152 | J18: 2.65 | K18: 1.47 | L18: 3.45 | M18: =K18+L18 -> 4.92 | N18: 0.4 | O18: =M18+N18 -> 5.32 | P18: 1.28 | Q18: 3 | S18: =((H18*(1-$S$2)+J18+$S$3)*G18*$S$6)*$AD$9 -> 2.6817298 | T18: =S18+(P18*$AD$9) -> 3.9617298 | U18: =S18+(Q18*$AD$9) -> 5.6817298 | V18: =((H18*(1-$V$2)+M18+$V$3)*G18*$S$6)*$AD$9 -> 4.6266264 | AB18: =A18*G18 -> 622.02422
A19: 726 | B19: 16 | C19: x | D19: 16 | E19: x | F19: 1 | G19: =(((B19*2+D19*2)/3.14)-F19)*F19*0.02504 -> 0.48532943 | H19: 1 | I19: =CONCATENATE(B19,D19,F19) -> 16161 | J19: 2.69 | K19: 1.2 | L19: 3.49 | M19: =K19+L19 -> 4.69 | N19: 0.4 | O19: =M19+N19 -> 5.09 | P19: 1.11672 | Q19: 1.92456 | S19: =((H19*(1-$S$2)+J19+$S$3)*G19*$S$6)*$AD$9 -> 1.5384943 | T19: =S19+(P19*$AD$9) -> 2.6552143 | U19: =S19+(Q19*$AD$9) -> 3.4630543 | AB19: =A19*G19 -> 352.34916
A20: 726 | B20: 16 | C20: x | D20: 16 | E20: x | F20: 1.5 | G20: =(((B20*2+D20*2)/3.14)-F20)*F20*0.02504 -> 0.70921414 | H20: 1 | I20: =CONCATENATE(B20,D20,F20) -> 16161,5 | J20: 2.61 | K20: 1.2 | L20: 3.41 | M20: =K20+L20 -> 4.61 | N20: 0.4 | O20: =M20+N20 -> 5.01 | P20: 1.11672 | Q20: 1.92456 | S20: =((H20*(1-$S$2)+J20+$S$3)*G20*$S$6)*$AD$9 -> 2.1914717 | T20: =S20+(P20*$AD$9) -> 3.3081917 | U20: =S20+(Q20*$AD$9) -> 4.1160317 | V20: =((H20*(1-$V$2)+M20+$V$3)*G20*$S$6)*$AD$9 -> 3.6099 | W20: =V20+P20*$AD$9 -> 4.72662 | X20: =V20+(Q20*$AD$9) -> 5.53446 | AB20: =A20*G20 -> 514.88947
A21: 726 | B21: 20 | C21: x | D21: 20 | E21: x | F21: 1 | G21: =(((B21*2+D21*2)/3.14)-F21)*F21*0.02504 -> 0.61292178 | H21: 1 | I21: =CONCATENATE(B21,D21,F21) -> 20201 | J21: 2.63 | K21: 1.2 | L21: 3.43 | M21: =K21+L21 -> 4.63 | N21: 0.4 | O21: =M21+N21 -> 5.03 | P21: 1.11672 | Q21: 2.41164 | S21: =((H21*(1-$S$2)+J21+$S$3)*G21*$S$6)*$AD$9 -> 1.9061867 | T21: =S21+(P21*$AD$9) -> 3.0229067 | U21: =S21+(Q21*$AD$9) -> 4.3178267 | AB21: =A21*G21 -> 444.98121
A22: 726 | B22: 20 | C22: x | D22: 20 | E22: x | F22: 1.2 | G22: =(((B22*2+D22*2)/3.14)-F22)*F22*0.02504 -> 0.72949654 | H22: 1 | I22: =CONCATENATE(B22,D22,F22) -> 20201,2 | J22: 2.6 | K22: 1.2 | L22: 3.4 | M22: =K22+L22 -> 4.6 | N22: 0.4 | O22: =M22+N22 -> 5 | P22: 1.11672 | Q22: 2.41164 | S22: =((H22*(1-$S$2)+J22+$S$3)*G22*$S$6)*$AD$9 -> 2.2468493 | T22: =S22+(P22*$AD$9) -> 3.3635693 | U22: =S22+(Q22*$AD$9) -> 4.6584893 | AB22: =A22*G22 -> 529.61449
A23: 726 | B23: 20 | C23: x | D23: 20 | E23: x | F23: 1.5 | G23: =(((B23*2+D23*2)/3.14)-F23)*F23*0.02504 -> 0.90060268 | H23: 1 | I23: =CONCATENATE(B23,D23,F23) -> 20201,5 | J23: 2.56 | K23: 1.2 | L23: 3.36 | M23: =K23+L23 -> 4.56 | N23: 0.4 | O23: =M23+N23 -> 4.96 | P23: 1.11672 | Q23: 2.41164 | S23: =((H23*(1-$S$2)+J23+$S$3)*G23*$S$6)*$AD$9 -> 2.7378321 | T23: =S23+(P23*$AD$9) -> 3.8545521 | U23: =S23+(Q23*$AD$9) -> 5.1494721 | V23: =((H23*(1-$V$2)+M23+$V$3)*G23*$S$6)*$AD$9 -> 4.5390375 | W23: =V23+P23*$AD$9 -> 5.6557575 | X23: =V23+(Q23*$AD$9) -> 6.9506775 | AB23: =A23*G23 -> 653.83754
A24: 726 | B24: 20 | C24: x | D24: 20 | E24: x | F24: 2 | G24: =(((B24*2+D24*2)/3.14)-F24)*F24*0.02504 -> 1.1757636 | H24: 1 | I24: =CONCATENATE(B24,D24,F24) -> 20202 | J24: 2.29 | K24: 1.47 | L24: 2.942 | M24: =K24+L24 -> 4.412 | N24: 0.4 | O24: =M24+N24 -> 4.812 | P24: 1.28304 | Q24: 3.35016 | S24: =((H24*(1-$S$2)+J24+$S$3)*G24*$S$6)*$AD$9 -> 3.2568651 | T24: =S24+(P24*$AD$9) -> 4.5399051 | U24: =S24+(Q24*$AD$9) -> 6.6070251 | V24: =((H24*(1-$V$2)+M24+$V$3)*G24*$S$6)*$AD$9 -> 5.7518354 | W24: =V24+P24*$AD$9 -> 7.0348754 | X24: =V24+(Q24*$AD$9) -> 9.1019954 | Y24: =((H24*(1-$Y$2)+O24+$Y$3)*G24*$S$6)*$AD$9 -> 6.2456561 | Z24: =Y24+P24*$AD$9 -> 7.5286961 | AA24: =Y24+(Q24*$AD$9) -> 9.5958161 | AB24: =A24*G24 -> 853.60435
A25: 486 | B25: 20 | C25: x | D25: 20 | E25: x | F25: 3 | G25: =(((B25*2+D25*2)/3.14)-F25)*F25*0.02504 -> 1.6885254 | H25: 1 | I25: =CONCATENATE(B25,D25,F25) -> 20203 | J25: 2.4 | K25: 1.2 | L25: 3.2 | M25: =K25+L25 -> 4.4 | N25: 0.4 | O25: =M25+N25 -> 4.8 | P25: 1.3 | Q25: 6.77 | S25: =((H25*(1-$S$2)+J25+$S$3)*G25*$S$6)*$AD$9 -> 4.862953 | T25: =S25+(P25*$AD$9) -> 6.162953 | U25: =S25+(Q25*$AD$9) -> 11.632953 | V25: =((H25*(1-$V$2)+M25+$V$3)*G25*$S$6)*$AD$9 -> 8.2400037 | W25: =V25+P25*$AD$9 -> 9.5400037 | X25: =V25+(Q25*$AD$9) -> 15.010004 | Y25: =((H25*(1-$Y$2)+O25+$Y$3)*G25*$S$6)*$AD$9 -> 8.9491844 | Z25: =Y25+P25*$AD$9 -> 10.249184 | AA25: =Y25+(Q25*$AD$9) -> 15.719184 | AB25: =A25*G25 -> 820.62332
A26: 726 | B26: 22 | C26: x | D26: 22 | E26: x | F26: 1.5 | G26: =(((B26*2+D26*2)/3.14)-F26)*F26*0.02504 -> 0.99629694 | H26: 1 | I26: =CONCATENATE(B26,D26,F26) -> 22221,5 | J26: 2.75 | K26: 1.2 | L26: 3.55 | M26: =K26+L26 -> 4.75 | N26: 0.4 | O26: =M26+N26 -> 5.15 | P26: 1.12 | Q26: 3.01 | S26: =((H26*(1-$S$2)+J26+$S$3)*G26*$S$6)*$AD$9 -> 3.2180391 | T26: =S26+(P26*$AD$9) -> 4.3380391 | U26: =S26+(Q26*$AD$9) -> 6.2280391 | V26: =((H26*(1-$V$2)+M26+$V$3)*G26*$S$6)*$AD$9 -> 5.210633 | W26: =V26+P26*$AD$9 -> 6.330633 | X26: =V26+(Q26*$AD$9) -> 8.220633 | AB26: =A26*G26 -> 723.31158
A27: 864 | B27: 25 | C27: x | D27: 25 | E27: x | F27: 1 | G27: =(((B27*2+D27*2)/3.14)-F27)*F27*0.02504 -> 0.77241223 | H27: 1 | I27: =CONCATENATE(B27,D27,F27) -> 25251 | J27: 2.59 | K27: 1.2 | L27: 3.39 | M27: =K27+L27 -> 4.59 | N27: 0.4 | O27: =M27+N27 -> 4.99 | P27: 1.11672 | Q27: 3.00564 | S27: =((H27*(1-$S$2)+J27+$S$3)*G27*$S$6)*$AD$9 -> 2.3713055 | T27: =S27+(P27*$AD$9) -> 3.4880255 | U27: =S27+(Q27*$AD$9) -> 5.3769455 | AB27: =A27*G27 -> 667.36417
A28: 864 | B28: 25 | C28: x | D28: 25 | E28: x | F28: 1.2 | G28: =(((B28*2+D28*2)/3.14)-F28)*F28*0.02504 -> 0.92088508 | H28: 1 | I28: =CONCATENATE(B28,D28,F28) -> 25251,2 | J28: 2.57 | K28: 1.2 | L28: 3.37 | M28: =K28+L28 -> 4.57 | N28: 0.4 | O28: =M28+N28 -> 4.97 | P28: 1.11672 | Q28: 3.00564 | S28: =((H28*(1-$S$2)+J28+$S$3)*G28*$S$6)*$AD$9 -> 2.8086995 | T28: =S28+(P28*$AD$9) -> 3.9254195 | U28: =S28+(Q28*$AD$9) -> 5.8143395 | AB28: =A28*G28 -> 795.6447
A29: 864 | B29: 25 | C29: x | D29: 25 | E29: x | F29: 1.5 | G29: =(((B29*2+D29*2)/3.14)-F29)*F29*0.02504 -> 1.1398383 | H29: 1 | I29: =CONCATENATE(B29,D29,F29) -> 25251,5 | J29: 2.51 | K29: 1.2 | L29: 3.31 | M29: =K29+L29 -> 4.51 | N29: 0.4 | O29: =M29+N29 -> 4.91 | P29: 1.11672 | Q29: 3.00564 | S29: =((H29*(1-$S$2)+J29+$S$3)*G29*$S$6)*$AD$9 -> 3.4081166 | T29: =S29+(P29*$AD$9) -> 4.5248366 | U29: =S29+(Q29*$AD$9) -> 6.4137566 | V29: =((H29*(1-$V$2)+M29+$V$3)*G29*$S$6)*$AD$9 -> 5.6877933 | W29: =V29+P29*$AD$9 -> 6.8045133 | X29: =V29+(Q29*$AD$9) -> 8.6934333 | AB29: =A29*G29 -> 984.82033
A30: 726 | B30: 25 | C30: x | D30: 25 | E30: x | F30: 2 | G30: =(((B30*2+D30*2)/3.14)-F30)*F30*0.02504 -> 1.4947445 | H30: 1 | I30: =CONCATENATE(B30,D30,F30) -> 25252 | J30: 2.24 | K30: 1.47 | L30: 2.89 | M30: =K30+L30 -> 4.36 | N30: 0.4 | O30: =M30+N30 -> 4.76 | P30: 1.28304 | Q30: 4.18176 | S30: =((H30*(1-$S$2)+J30+$S$3)*G30*$S$6)*$AD$9 -> 4.0657049 | T30: =S30+(P30*$AD$9) -> 5.3487449 | U30: =S30+(Q30*$AD$9) -> 8.2474649 | V30: =((H30*(1-$V$2)+M30+$V$3)*G30*$S$6)*$AD$9 -> 7.2345632 | W30: =V30+P30*$AD$9 -> 8.5176032 | X30: =V30+(Q30*$AD$9) -> 11.416323 | Y30: =((H30*(1-$Y$2)+O30+$Y$3)*G30*$S$6)*$AD$9 -> 7.8623559 | Z30: =Y30+P30*$AD$9 -> 9.1453959 | AA30: =Y30+(Q30*$AD$9) -> 12.044116 | AB30: =A30*G30 -> 1085.1845
A31: 486 | B31: 25 | C31: x | D31: 25 | E31: x | F31: 2.5 | G31: =(((B31*2+D31*2)/3.14)-F31)*F31*0.02504 -> 1.8371306 | H31: 1 | I31: =CONCATENATE(B31,D31,F31) -> 25252,5 | J31: 2.35 | K31: 1.2 | L31: 3.15 | M31: =K31+L31 -> 4.35 | N31: 0.4 | O31: =M31+N31 -> 4.75 | P31: 1.52 | Q31: 6.77 | S31: =((H31*(1-$S$2)+J31+$S$3)*G31*$S$6)*$AD$9 -> 5.1990795 | T31: =S31+(P31*$AD$9) -> 6.7190795 | U31: =S31+(Q31*$AD$9) -> 11.96908 | AB31: =A31*G31 -> 892.84546
A32: 486 | B32: 25 | C32: x | D32: 25 | E32: x | F32: 3 | G32: =(((B32*2+D32*2)/3.14)-F32)*F32*0.02504 -> 2.1669967 | H32: 1 | I32: =CONCATENATE(B32,D32,F32) -> 25253 | J32: 2.3 | K32: 1.2 | L32: 3.003 | M32: =K32+L32 -> 4.203 | N32: 0.4 | O32: =M32+N32 -> 4.603 | P32: 1.52064 | Q32: 6.7716 | S32: =((H32*(1-$S$2)+J32+$S$3)*G32*$S$6)*$AD$9 -> 6.0242508 | T32: =S32+(P32*$AD$9) -> 7.5448908 | U32: =S32+(Q32*$AD$9) -> 12.795851 | AB32: =A32*G32 -> 1053.1604
A33: 600 | B33: 30 | C33: x | D33: 30 | E33: x | F33: 1 | G33: =(((B33*2+D33*2)/3.14)-F33)*F33*0.02504 -> 0.93190268 | H33: 1 | I33: =CONCATENATE(B33,D33,F33) -> 30301 | J33: 2.52 | K33: 1.2 | L33: 3.32 | M33: =K33+L33 -> 4.52 | N33: 0.4 | O33: =M33+N33 -> 4.92 | P33: 1.11672 | Q33: 3.61152 | S33: =((H33*(1-$S$2)+J33+$S$3)*G33*$S$6)*$AD$9 -> 2.795708 | T33: =S33+(P33*$AD$9) -> 3.912428 | U33: =S33+(Q33*$AD$9) -> 6.407228 | AB33: =A33*G33 -> 559.14161
A34: 600 | B34: 30 | C34: x | D34: 30 | E34: x | F34: 1.2 | G34: =(((B34*2+D34*2)/3.14)-F34)*F34*0.02504 -> 1.1122736 | H34: 1 | I34: =CONCATENATE(B34,D34,F34) -> 30301,2 | J34: 2.46 | K34: 1.2 | L34: 3.26 | M34: =K34+L34 -> 4.46 | N34: 0.4 | O34: =M34+N34 -> 4.86 | P34: 1.11672 | Q34: 3.61152 | S34: =((H34*(1-$S$2)+J34+$S$3)*G34*$S$6)*$AD$9 -> 3.2700844 | T34: =S34+(P34*$AD$9) -> 4.3868044 | U34: =S34+(Q34*$AD$9) -> 6.8816044 | AB34: =A34*G34 -> 667.36417
A35: 600 | B35: 30 | C35: x | D35: 30 | E35: x | F35: 1.5 | G35: =(((B35*2+D35*2)/3.14)-F35)*F35*0.02504 -> 1.379074 | H35: 1 | I35: =CONCATENATE(B35,D35,F35) -> 30301,5 | J35: 2.41 | K35: 1.2 | L35: 3.21 | M35: =K35+L35 -> 4.41 | N35: 0.4 | O35: =M35+N35 -> 4.81 | P35: 1.11672 | Q35: 3.61152 | S35: =((H35*(1-$S$2)+J35+$S$3)*G35*$S$6)*$AD$9 -> 3.9855239 | T35: =S35+(P35*$AD$9) -> 5.1022439 | U35: =S35+(Q35*$AD$9) -> 7.5970439 | V35: =((H35*(1-$V$2)+M35+$V$3)*G35*$S$6)*$AD$9 -> 6.7436719 | W35: =V35+P35*$AD$9 -> 7.8603919 | X35: =V35+(Q35*$AD$9) -> 10.355192 | AB35: =A35*G35 -> 827.44441
A36: 600 | B36: 30 | C36: x | D36: 30 | E36: x | F36: 2 | G36: =(((B36*2+D36*2)/3.14)-F36)*F36*0.02504 -> 1.8137254 | H36: 1 | I36: =CONCATENATE(B36,D36,F36) -> 30302 | J36: 2.14 | K36: 1.47 | L36: 2.79 | M36: =K36+L36 -> 4.26 | N36: 0.4 | O36: =M36+N36 -> 4.66 | P36: 1.28304 | Q36: 5.01336 | S36: =((H36*(1-$S$2)+J36+$S$3)*G36*$S$6)*$AD$9 -> 4.7519604 | T36: =S36+(P36*$AD$9) -> 6.0350004 | U36: =S36+(Q36*$AD$9) -> 9.7653204 | V36: =((H36*(1-$V$2)+M36+$V$3)*G36*$S$6)*$AD$9 -> 8.5970582 | W36: =V36+P36*$AD$9 -> 9.8800982 | X36: =V36+(Q36*$AD$9) -> 13.610418 | Y36: =((H36*(1-$Y$2)+O36+$Y$3)*G36*$S$6)*$AD$9 -> 9.3588228 | Z36: =Y36+P36*$AD$9 -> 10.641863 | AA36: =Y36+(Q36*$AD$9) -> 14.372183 | AB36: =A36*G36 -> 1088.2352
A37: 384 | B37: 30 | C37: x | D37: 30 | E37: x | F37: 2.5 | G37: =(((B37*2+D37*2)/3.14)-F37)*F37*0.02504 -> 2.2358567 | H37: 1 | I37: =CONCATENATE(B37,D37,F37) -> 30302,5 | J37: 2.16 | K37: 1.3 | L37: 2.761 | M37: =K37+L37 -> 4.061 | N37: 0.4 | O37: =M37+N37 -> 4.461 | P37: 1.46124 | Q37: 7.7814 | S37: =((H37*(1-$S$2)+J37+$S$3)*G37*$S$6)*$AD$9 -> 5.9026617 | T37: =S37+(P37*$AD$9) -> 7.3639017 | U37: =S37+(Q37*$AD$9) -> 13.684062 | V37: =((H37*(1-$V$2)+M37+$V$3)*G37*$S$6)*$AD$9 -> 10.153025 | W37: =V37+P37*$AD$9 -> 11.614265 | X37: =V37+(Q37*$AD$9) -> 17.934425 | AB37: =A37*G37 -> 858.56897
A38: 384 | B38: 30 | C38: x | D38: 30 | E38: x | F38: 3 | G38: =(((B38*2+D38*2)/3.14)-F38)*F38*0.02504 -> 2.645468 | H38: 1 | I38: =CONCATENATE(B38,D38,F38) -> 30303 | J38: 2.13 | K38: 1.2 | L38: 2.833 | M38: =K38+L38 -> 4.033 | N38: 0.4 | O38: =M38+N38 -> 4.433 | P38: 1.61568 | Q38: 8.12592 | S38: =((H38*(1-$S$2)+J38+$S$3)*G38*$S$6)*$AD$9 -> 6.9046715 | T38: =S38+(P38*$AD$9) -> 8.5203515 | U38: =S38+(Q38*$AD$9) -> 15.030592 | V38: =((H38*(1-$V$2)+M38+$V$3)*G38*$S$6)*$AD$9 -> 11.938997 | W38: =V38+P38*$AD$9 -> 13.554677 | X38: =V38+(Q38*$AD$9) -> 20.064917 | Y38: =((H38*(1-$Y$2)+O38+$Y$3)*G38*$S$6)*$AD$9 -> 13.050094 | Z38: =Y38+P38*$AD$9 -> 14.665774 | AA38: =Y38+(Q38*$AD$9) -> 21.176014 | AB38: =A38*G38 -> 1015.8597
A39: 600 | B39: 35 | C39: x | D39: 35 | E39: x | F39: 1 | G39: =(((B39*2+D39*2)/3.14)-F39)*F39*0.02504 -> 1.0913931 | H39: 1 | I39: =CONCATENATE(B39,D39,F39) -> 35351 | J39: 2.58 | K39: 1.2 | L39: 3.38 | M39: =K39+L39 -> 4.58 | N39: 0.4 | O39: =M39+N39 -> 4.98 | P39: 1.3068 | Q39: 4.2174 | S39: =((H39*(1-$S$2)+J39+$S$3)*G39*$S$6)*$AD$9 -> 3.339663 | T39: =S39+(P39*$AD$9) -> 4.646463 | U39: =S39+(Q39*$AD$9) -> 7.557063 | AB39: =A39*G39 -> 654.83587
A40: 600 | B40: 35 | C40: x | D40: 35 | E40: x | F40: 1.2 | G40: =(((B40*2+D40*2)/3.14)-F40)*F40*0.02504 -> 1.3036621 | H40: 1 | I40: =CONCATENATE(B40,D40,F40) -> 35351,2 | J40: 2.49 | K40: 1.2 | L40: 3.29 | M40: =K40+L40 -> 4.49 | N40: 0.4 | O40: =M40+N40 -> 4.89 | P40: 1.3068 | Q40: 4.2174 | S40: =((H40*(1-$S$2)+J40+$S$3)*G40*$S$6)*$AD$9 -> 3.8718766 | T40: =S40+(P40*$AD$9) -> 5.1786766 | U40: =S40+(Q40*$AD$9) -> 8.0892766 | AB40: =A40*G40 -> 782.19729
A41: 600 | B41: 35 | C41: x | D41: 35 | E41: x | F41: 1.5 | G41: =(((B41*2+D41*2)/3.14)-F41)*F41*0.02504 -> 1.6183097 | H41: 1 | I41: =CONCATENATE(B41,D41,F41) -> 35351,5 | J41: 2.42 | K41: 1.2 | L41: 3.22 | M41: =K41+L41 -> 4.42 | N41: 0.4 | O41: =M41+N41 -> 4.82 | P41: 1.31868 | Q41: 4.2174 | S41: =((H41*(1-$S$2)+J41+$S$3)*G41*$S$6)*$AD$9 -> 4.6930981 | T41: =S41+(P41*$AD$9) -> 6.0117781 | U41: =S41+(Q41*$AD$9) -> 8.9104981 | V41: =((H41*(1-$V$2)+M41+$V$3)*G41*$S$6)*$AD$9 -> 7.9297174 | W41: =V41+P41*$AD$9 -> 9.2483974 | X41: =V41+(Q41*$AD$9) -> 12.147117 | AB41: =A41*G41 -> 970.98581
...

Sheet ROUND TIG-LASER
A1: PRICE LIST MAY '26 | X1: DC 8.2_03
D2: DISCOUNT | O2: 0.55 | P2: 0.55 | Q2: 0.55
D3: Alloy Surcharge €/Kg | O3: 0 | P3: 0 | Q3: 0
D4: ROUND TIG-LASER | O4: 304L | P4: 316L | Q4: 316Ti | AA4: DKK | AB4: 0
AA5: EUR | AB5: 1
AA6: GBP | AB6: 0.87
E7: EXTRA % | O7: 1 | AA7: NOK | AB7: 0
D8: Rate | O8: EUR | AA8: SEK | AB8: 0
AA9: USD | AB9: 1.16
O10: BRUSHED NOT ANNEALED | S10: O.D. POLISHED G.240/320 | W10: O.D. MIRROR POLISHED
C11: MT | D11: Dimension | G11: €/kg | I11: FISSO | O11: 1.4301 | P11: 1.4404 | Q11: 1.4571 | S11: 1.4301 | T11: 1.4404 | U11: 1.4571 | W11: 1.4301 | X11: 1.4404 | Y11: 1.4571 | AA11: IN USO | AB11: =VLOOKUP(O8,$AA$4:$AB$9,2) -> 1
A12: DN | B12: POL. | C12: BDL | D12: Diam. | E12: Thk. | F12: kg/mt | G12: €/kg | I12: 304 | J12: E316L | K12: E316Ti | O12: 304 | P12: 316 L / Ti | Q12: 316 Ti | R12: SAT | S12: 304 | T12: 316 L / Ti | U12: 316 Ti | V12: LUC | W12: 304 | X12: 316 L / Ti | Y12: 316 Ti | Z12: Kg/Bdl
C13: 1050 | D13: 6 | E13: 1 | F13: =(D13-E13)*E13*0.02504 -> 0.1252 | G13: 1 | H13: =CONCATENATE(D13,E13) -> 61 | I13: 7.65 | J13: 1.9 | K13: 2.3 | L13: =I13+J13 -> 9.55 | M13: =I13+K13 -> 9.95 | O13: =((G13*(1-$O$2)+I13+$O$3)*F13*$O$7)*$AB$11 -> 1.01412 | R13: 0 | V13: 0 | Z13: =F13*C13 -> 131.46
C14: 1050 | D14: 8 | E14: 1 | F14: =(D14-E14)*E14*0.02504 -> 0.17528 | G14: 1 | H14: =CONCATENATE(D14,E14) -> 81 | I14: 6.2 | J14: 1.9 | K14: 2.3 | L14: =I14+J14 -> 8.1 | M14: =I14+K14 -> 8.5 | O14: =((G14*(1-$O$2)+I14+$O$3)*F14*$O$7)*$AB$11 -> 1.165612 | R14: 0 | V14: 0 | Z14: =F14*C14 -> 184.044
C15: 810 | D15: 10 | E15: 1 | F15: =(D15-E15)*E15*0.02504 -> 0.22536 | G15: 1 | H15: =CONCATENATE(D15,E15) -> 101 | I15: 4.74 | J15: 1.9 | K15: 2.3 | L15: =I15+J15 -> 6.64 | M15: =I15+K15 -> 7.04 | O15: =((G15*(1-$O$2)+I15+$O$3)*F15*$O$7)*$AB$11 -> 1.1696184 | R15: 0.69 | S15: =O15+R15*$AB$11 -> 1.8596184 | V15: 1.25 | W15: =O15+V15*$AB$11 -> 2.4196184 | Z15: =F15*C15 -> 182.5416
C16: 810 | D16: 10 | E16: 1.5 | F16: =(D16-E16)*E16*0.02504 -> 0.31926 | G16: 1 | H16: =CONCATENATE(D16,E16) -> 101,5 | I16: 4.532 | J16: 1.9 | K16: 2.3 | L16: =I16+J16 -> 6.432 | M16: =I16+K16 -> 6.832 | O16: =((G16*(1-$O$2)+I16+$O$3)*F16*$O$7)*$AB$11 -> 1.5905533 | P16: =((G16*(1-$P$2)+I16+J16+$P$3)*F16*$O$7)*$AB$11 -> 2.1971473 | R16: 0.69 | S16: =O16+R16*$AB$11 -> 2.2805533 | V16: 1.25 | W16: =O16+V16*$AB$11 -> 2.8405533 | Z16: =F16*C16 -> 258.6006
C17: 810 | D17: 12 | E17: 1 | F17: =(D17-E17)*E17*0.02504 -> 0.27544 | G17: 1 | H17: =CONCATENATE(D17,E17) -> 121 | I17: 4.312 | J17: 1.9 | K17: 2.3 | L17: =I17+J17 -> 6.212 | M17: =I17+K17 -> 6.612 | O17: =((G17*(1-$O$2)+I17+$O$3)*F17*$O$7)*$AB$11 -> 1.3116453 | R17: 0.68904 | S17: =O17+R17*$AB$11 -> 2.0006853 | V17: 1.25 | W17: =O17+V17*$AB$11 -> 2.5616453 | Z17: =F17*C17 -> 223.1064
C18: 810 | D18: 12 | E18: 1.5 | F18: =(D18-E18)*E18*0.02504 -> 0.39438 | G18: 1 | H18: =CONCATENATE(D18,E18) -> 121,5 | I18: 4.382 | J18: 1.9 | K18: 2.3 | L18: =I18+J18 -> 6.282 | M18: =I18+K18 -> 6.682 | O18: =((G18*(1-$O$2)+I18+$O$3)*F18*$O$7)*$AB$11 -> 1.9056442 | P18: =((G18*(1-$P$2)+I18+J18+$P$3)*F18*$O$7)*$AB$11 -> 2.6549662 | R18: 0.68904 | S18: =O18+R18*$AB$11 -> 2.5946842 | T18: =P18+R18*$AB$11 -> 3.3440062 | V18: 1.2474 | W18: =O18+V18*$AB$11 -> 3.1530442 | X18: =P18+V18*$AB$11 -> 3.9023662 | Z18: =F18*C18 -> 319.4478
C19: 810 | D19: 12 | E19: 2 | F19: =(D19-E19)*E19*0.02504 -> 0.5008 | G19: 1 | H19: =CONCATENATE(D19,E19) -> 122 | I19: 4.15 | J19: 2.05 | K19: 2.45 | L19: =I19+J19 -> 6.2 | M19: =I19+K19 -> 6.6 | O19: =((G19*(1-$O$2)+I19+$O$3)*F19*$O$7)*$AB$11 -> 2.30368 | P19: =((G19*(1-$P$2)+I19+J19+$P$3)*F19*$O$7)*$AB$11 -> 3.33032 | R19: 0.71 | S19: =O19+R19*$AB$11 -> 3.01368 | V19: 1.2 | W19: =O19+V19*$AB$11 -> 3.50368 | Z19: =F19*C19 -> 405.648
C20: 810 | D20: 13 | E20: 1 | F20: =(D20-E20)*E20*0.02504 -> 0.30048 | G20: 1 | H20: =CONCATENATE(D20,E20) -> 131 | I20: 4.09 | J20: 1.9 | K20: 2.3 | L20: =I20+J20 -> 5.99 | M20: =I20+K20 -> 6.39 | O20: =((G20*(1-$O$2)+I20+$O$3)*F20*$O$7)*$AB$11 -> 1.3641792 | R20: 0.68904 | S20: =O20+R20*$AB$11 -> 2.0532192 | V20: 1.2474 | Z20: =F20*C20 -> 243.3888
C21: 810 | D21: 13 | E21: 1.5 | F21: =(D21-E21)*E21*0.02504 -> 0.43194 | G21: 1 | H21: =CONCATENATE(D21,E21) -> 131,5 | I21: 3.92 | J21: 1.9 | K21: 2.3 | L21: =I21+J21 -> 5.82 | M21: =I21+K21 -> 6.22 | O21: =((G21*(1-$O$2)+I21+$O$3)*F21*$O$7)*$AB$11 -> 1.8875778 | P21: =((G21*(1-$P$2)+I21+J21+$P$3)*F21*$O$7)*$AB$11 -> 2.7082638 | R21: 0.69 | S21: =O21+R21*$AB$11 -> 2.5775778 | T21: =P21+R21*$AB$11 -> 3.3982638 | V21: 1.25 | Z21: =F21*C21 -> 349.8714
C22: 678 | D22: 14 | E22: 1 | F22: =(D22-E22)*E22*0.02504 -> 0.32552 | G22: 1 | H22: =CONCATENATE(D22,E22) -> 141 | I22: 3.582 | J22: 1.9 | K22: 2.3 | L22: =I22+J22 -> 5.482 | M22: =I22+K22 -> 5.882 | O22: =((G22*(1-$O$2)+I22+$O$3)*F22*$O$7)*$AB$11 -> 1.3124966 | R22: 0.68904 | S22: =O22+R22*$AB$11 -> 2.0015366 | V22: 1.2474 | W22: =O22+V22*$AB$11 -> 2.5598966 | Z22: =F22*C22 -> 220.70256
C23: 678 | D23: 14 | E23: 1.5 | F23: =(D23-E23)*E23*0.02504 -> 0.4695 | G23: 1 | H23: =CONCATENATE(D23,E23) -> 141,5 | I23: 3.642 | J23: 1.9 | K23: 2.3 | L23: =I23+J23 -> 5.542 | M23: =I23+K23 -> 5.942 | O23: =((G23*(1-$O$2)+I23+$O$3)*F23*$O$7)*$AB$11 -> 1.921194 | P23: =((G23*(1-$P$2)+I23+J23+$P$3)*F23*$O$7)*$AB$11 -> 2.813244 | R23: 0.68904 | S23: =O23+R23*$AB$11 -> 2.610234 | T23: =P23+R23*$AB$11 -> 3.502284 | V23: 1.2474 | W23: =O23+V23*$AB$11 -> 3.168594 | X23: =P23+V23*$AB$11 -> 4.060644 | Z23: =F23*C23 -> 318.321
C24: 678 | D24: 14 | E24: 2 | F24: =(D24-E24)*E24*0.02504 -> 0.60096 | G24: 1 | H24: =CONCATENATE(D24,E24) -> 142 | I24: 3.51 | J24: 2.05 | K24: 2.45 | L24: =I24+J24 -> 5.56 | M24: =I24+K24 -> 5.96 | O24: =((G24*(1-$O$2)+I24+$O$3)*F24*$O$7)*$AB$11 -> 2.3798016 | P24: =((G24*(1-$P$2)+I24+J24+$P$3)*F24*$O$7)*$AB$11 -> 3.6117696 | R24: 0.7128 | S24: =O24+R24*$AB$11 -> 3.0926016 | T24: =P24+R24*$AB$11 -> 4.3245696 | V24: 1.2474 | W24: =O24+V24*$AB$11 -> 3.6272016 | X24: =P24+V24*$AB$11 -> 4.8591696 | Z24: =F24*C24 -> 407.45088
C25: 678 | D25: 15 | E25: 1 | F25: =(D25-E25)*E25*0.02504 -> 0.35056 | G25: 1 | H25: =CONCATENATE(D25,E25) -> 151 | I25: 3.542 | J25: 1.9 | K25: 2.3 | L25: =I25+J25 -> 5.442 | M25: =I25+K25 -> 5.842 | O25: =((G25*(1-$O$2)+I25+$O$3)*F25*$O$7)*$AB$11 -> 1.3994355 | R25: 0.68904 | S25: =O25+R25*$AB$11 -> 2.0884755 | V25: 1.2474 | W25: =O25+V25*$AB$11 -> 2.6468355 | Z25: =F25*C25 -> 237.67968
C26: 678 | D26: 15 | E26: 1.2 | F26: =(D26-E26)*E26*0.02504 -> 0.4146624 | G26: 1 | H26: =CONCATENATE(D26,E26) -> 151,2 | I26: 3.58 | J26: 1.9 | K26: 2.3 | L26: =I26+J26 -> 5.48 | M26: =I26+K26 -> 5.88 | O26: =((G26*(1-$O$2)+I26+$O$3)*F26*$O$7)*$AB$11 -> 1.6710895 | R26: 0.69 | S26: =O26+R26*$AB$11 -> 2.3610895 | V26: 1.25 | W26: =O26+V26*$AB$11 -> 2.9210895 | Z26: =F26*C26 -> 281.14111
C27: 678 | D27: 15 | E27: 1.5 | F27: =(D27-E27)*E27*0.02504 -> 0.50706 | G27: 1 | H27: =CONCATENATE(D27,E27) -> 151,5 | I27: 3.602 | J27: 1.9 | K27: 2.3 | L27: =I27+J27 -> 5.502 | M27: =I27+K27 -> 5.902 | O27: =((G27*(1-$O$2)+I27+$O$3)*F27*$O$7)*$AB$11 -> 2.0546071 | P27: =((G27*(1-$P$2)+I27+J27+$P$3)*F27*$O$7)*$AB$11 -> 3.0180211 | R27: 0.68904 | S27: =O27+R27*$AB$11 -> 2.7436471 | T27: =P27+R27*$AB$11 -> 3.7070611 | V27: 1.2474 | W27: =O27+V27*$AB$11 -> 3.3020071 | X27: =P27+V27*$AB$11 -> 4.2654211 | Z27: =F27*C27 -> 343.78668
C28: 678 | D28: 15 | E28: 2 | F28: =(D28-E28)*E28*0.02504 -> 0.65104 | G28: 1 | H28: =CONCATENATE(D28,E28) -> 152 | I28: 3.56 | J28: 2.05 | K28: 2.45 | L28: =I28+J28 -> 5.61 | M28: =I28+K28 -> 6.01 | O28: =((G28*(1-$O$2)+I28+$O$3)*F28*$O$7)*$AB$11 -> 2.6106704 | P28: =((G28*(1-$P$2)+I28+J28+$P$3)*F28*$O$7)*$AB$11 -> 3.9453024 | R28: 0.7128 | S28: =O28+R28*$AB$11 -> 3.3234704 | T28: =P28+R28*$AB$11 -> 4.6581024 | V28: 1.2474 | W28: =O28+V28*$AB$11 -> 3.8580704 | X28: =P28+V28*$AB$11 -> 5.1927024 | Z28: =F28*C28 -> 441.40512
C29: 678 | D29: 16 | E29: 1 | F29: =(D29-E29)*E29*0.02504 -> 0.3756 | G29: 1 | H29: =CONCATENATE(D29,E29) -> 161 | I29: 3.462 | J29: 1.9 | K29: 2.3 | L29: =I29+J29 -> 5.362 | M29: =I29+K29 -> 5.762 | O29: =((G29*(1-$O$2)+I29+$O$3)*F29*$O$7)*$AB$11 -> 1.4693472 | R29: 0.68904 | S29: =O29+R29*$AB$11 -> 2.1583872 | V29: 1.2474 | W29: =O29+V29*$AB$11 -> 2.7167472 | Z29: =F29*C29 -> 254.6568
C30: 678 | D30: 16 | E30: 1.2 | F30: =(D30-E30)*E30*0.02504 -> 0.4447104 | G30: 1 | H30: =CONCATENATE(D30,E30) -> 161,2 | I30: 3.31 | J30: 1.9 | K30: 2.3 | L30: =I30+J30 -> 5.21 | M30: =I30+K30 -> 5.61 | O30: =((G30*(1-$O$2)+I30+$O$3)*F30*$O$7)*$AB$11 -> 1.6721111 | R30: 0.68904 | S30: =O30+R30*$AB$11 -> 2.3611511 | V30: 1.2474 | W30: =O30+V30*$AB$11 -> 2.9195111 | Z30: =F30*C30 -> 301.51365
C31: 678 | D31: 16 | E31: 1.5 | F31: =(D31-E31)*E31*0.02504 -> 0.54462 | G31: 1 | H31: =CONCATENATE(D31,E31) -> 161,5 | I31: 3.412 | J31: 1.9 | K31: 2.3 | L31: =I31+J31 -> 5.312 | M31: =I31+K31 -> 5.712 | O31: =((G31*(1-$O$2)+I31+$O$3)*F31*$O$7)*$AB$11 -> 2.1033224 | P31: =((G31*(1-$P$2)+I31+J31+$P$3)*F31*$O$7)*$AB$11 -> 3.1381004 | Q31: =((G31*(1-$Q$2)+I31+K31+$Q$3)*F31*$O$7)*$AB$11 -> 3.3559484 | R31: 0.68904 | S31: =O31+R31*$AB$11 -> 2.7923624 | T31: =P31+R31*$AB$11 -> 3.8271404 | U31: =Q31+R31*$AB$11 -> 4.0449884 | V31: 1.2474 | W31: =O31+V31*$AB$11 -> 3.3507224 | X31: =P31+V31*$AB$11 -> 4.3855004 | Y31: =Q31+V31*$AB$11 -> 4.6033484 | Z31: =F31*C31 -> 369.25236
C32: 678 | D32: 16 | E32: 2 | F32: =(D32-E32)*E32*0.02504 -> 0.70112 | G32: 1 | H32: =CONCATENATE(D32,E32) -> 162 | I32: 3.31 | J32: 2.05 | K32: 2.45 | L32: =I32+J32 -> 5.36 | M32: =I32+K32 -> 5.76 | O32: =((G32*(1-$O$2)+I32+$O$3)*F32*$O$7)*$AB$11 -> 2.6362112 | P32: =((G32*(1-$P$2)+I32+J32+$P$3)*F32*$O$7)*$AB$11 -> 4.0735072 | Q32: =((G32*(1-$Q$2)+I32+K32+$Q$3)*F32*$O$7)*$AB$11 -> 4.3539552 | R32: 0.7128 | S32: =O32+R32*$AB$11 -> 3.3490112 | T32: =P32+R32*$AB$11 -> 4.7863072 | U32: =Q32+R32*$AB$11 -> 5.0667552 | V32: 1.2474 | W32: =O32+V32*$AB$11 -> 3.8836112 | X32: =P32+V32*$AB$11 -> 5.3209072 | Y32: =Q32+V32*$AB$11 -> 5.6013552 | Z32: =F32*C32 -> 475.35936
A33: 10 | B33: 3/8" | C33: 678 | D33: 17.2 | E33: 1.5 | F33: =(D33-E33)*E33*0.02504 -> 0.589692 | G33: 1 | H33: =CONCATENATE(D33,E33) -> 17,21,5 | I33: 3.212 | J33: 1.9 | K33: 2.3 | L33: =I33+J33 -> 5.112 | M33: =I33+K33 -> 5.512 | O33: =((G33*(1-$O$2)+I33+$O$3)*F33*$O$7)*$AB$11 -> 2.1594521 | P33: =((G33*(1-$P$2)+I33+J33+$P$3)*F33*$O$7)*$AB$11 -> 3.2798669 | Q33: =((G33*(1-$Q$2)+I33+K33+$Q$3)*F33*$O$7)*$AB$11 -> 3.5157437 | R33: 0.68904 | S33: =O33+R33*$AB$11 -> 2.8484921 | T33: =P33+R33*$AB$11 -> 3.9689069 | U33: =Q33+R33*$AB$11 -> 4.2047837 | V33: 1.2474 | W33: =O33+V33*$AB$11 -> 3.4068521 | X33: =P33+V33*$AB$11 -> 4.5272669 | Y33: =Q33+V33*$AB$11 -> 4.7631437 | Z33: =F33*C33 -> 399.81118
C34: 678 | D34: 17.2 | E34: 1.6 | F34: =(D34-E34)*E34*0.02504 -> 0.6249984 | G34: 1 | H34: =CONCATENATE(D34,E34) -> 17,21,6 | I34: 3.212 | J34: 1.9 | K34: 2.3 | L34: =I34+J34 -> 5.112 | M34: =I34+K34 -> 5.512 | O34: =((G34*(1-$O$2)+I34+$O$3)*F34*$O$7)*$AB$11 -> 2.2887441 | P34: =((G34*(1-$P$2)+I34+J34+$P$3)*F34*$O$7)*$AB$11 -> 3.4762411 | R34: 0.68904 | S34: =O34+R34*$AB$11 -> 2.9777841 | V34: 1.2474 | Z34: =F34*C34 -> 423.74892
C35: 678 | D35: 17.2 | E35: 2 | F35: =(D35-E35)*E35*0.02504 -> 0.761216 | G35: 1 | H35: =CONCATENATE(D35,E35) -> 17,22 | I35: 2.96 | J35: 2.05 | K35: 2.45 | L35: =I35+J35 -> 5.01 | M35: =I35+K35 -> 5.41 | O35: =((G35*(1-$O$2)+I35+$O$3)*F35*$O$7)*$AB$11 -> 2.5957466 | P35: =((G35*(1-$P$2)+I35+J35+$P$3)*F35*$O$7)*$AB$11 -> 4.1562394 | Q35: =((G35*(1-$Q$2)+I35+K35+$Q$3)*F35*$O$7)*$AB$11 -> 4.4607258 | R35: 0.7128 | S35: =O35+R35*$AB$11 -> 3.3085466 | T35: =P35+R35*$AB$11 -> 4.8690394 | U35: =Q35+R35*$AB$11 -> 5.1735258 | V35: 1.2474 | W35: =O35+V35*$AB$11 -> 3.8431466 | X35: =P35+V35*$AB$11 -> 5.4036394 | Y35: =Q35+V35*$AB$11 -> 5.7081258 | Z35: =F35*C35 -> 516.10445
C36: 678 | D36: 17.2 | E36: 2.5 | F36: =(D36-E36)*E36*0.02504 -> 0.92022 | G36: 1 | H36: =CONCATENATE(D36,E36) -> 17,22,5 | I36: 3.11 | J36: 1.9 | K36: 2.3 | L36: =I36+J36 -> 5.01 | M36: =I36+K36 -> 5.41 | O36: =((G36*(1-$O$2)+I36+$O$3)*F36*$O$7)*$AB$11 -> 3.2759832 | P36: =((G36*(1-$P$2)+I36+J36+$P$3)*F36*$O$7)*$AB$11 -> 5.0244012 | Q36: =((G36*(1-$Q$2)+I36+K36+$Q$3)*F36*$O$7)*$AB$11 -> 5.3924892 | R36: 0.86 | S36: =O36+R36*$AB$11 -> 4.1359832 | T36: =P36+R36*$AB$11 -> 5.8844012 | U36: =Q36+R36*$AB$11 -> 6.2524892 | V36: 1.72 | W36: =O36+V36*$AB$11 -> 4.9959832 | X36: =P36+V36*$AB$11 -> 6.7444012 | Y36: =Q36+V36*$AB$11 -> 7.1124892 | Z36: =F36*C36 -> 623.90916
C37: 678 | D37: 18 | E37: 1 | F37: =(D37-E37)*E37*0.02504 -> 0.42568 | G37: 1 | H37: =CONCATENATE(D37,E37) -> 181 | I37: 3.362 | J37: 1.9 | K37: 2.3 | L37: =I37+J37 -> 5.262 | M37: =I37+K37 -> 5.662 | O37: =((G37*(1-$O$2)+I37+$O$3)*F37*$O$7)*$AB$11 -> 1.6226922 | R37: 0.68904 | S37: =O37+R37*$AB$11 -> 2.3117322 | V37: 1.2474 | W37: =O37+V37*$AB$11 -> 2.8700922 | Z37: =F37*C37 -> 288.61104
C38: 678 | D38: 18 | E38: 1.2 | F38: =(D38-E38)*E38*0.02504 -> 0.5048064 | G38: 1 | H38: =CONCATENATE(D38,E38) -> 181,2 | I38: 3.11 | J38: 1.9 | K38: 2.3 | L38: =I38+J38 -> 5.01 | M38: =I38+K38 -> 5.41 | O38: =((G38*(1-$O$2)+I38+$O$3)*F38*$O$7)*$AB$11 -> 1.7971108 | R38: 0.68904 | S38: =O38+R38*$AB$11 -> 2.4861508 | V38: 1.2474 | W38: =O38+V38*$AB$11 -> 3.0445108 | Z38: =F38*C38 -> 342.25874
C39: 678 | D39: 18 | E39: 1.5 | F39: =(D39-E39)*E39*0.02504 -> 0.61974 | G39: 1 | H39: =CONCATENATE(D39,E39) -> 181,5 | I39: 3.322 | J39: 1.9 | K39: 2.3 | L39: =I39+J39 -> 5.222 | M39: =I39+K39 -> 5.622 | O39: =((G39*(1-$O$2)+I39+$O$3)*F39*$O$7)*$AB$11 -> 2.3376593 | P39: =((G39*(1-$P$2)+I39+J39+$P$3)*F39*$O$7)*$AB$11 -> 3.5151653 | Q39: =((G39*(1-$Q$2)+I39+K39+$Q$3)*F39*$O$7)*$AB$11 -> 3.7630613 | R39: 0.68904 | S39: =O39+R39*$AB$11 -> 3.0266993 | T39: =P39+R39*$AB$11 -> 4.2042053 | U39: =Q39+R39*$AB$11 -> 4.4521013 | V39: 1.2474 | W39: =O39+V39*$AB$11 -> 3.5850593 | X39: =P39+V39*$AB$11 -> 4.7625653 | Y39: =Q39+V39*$AB$11 -> 5.0104613 | Z39: =F39*C39 -> 420.18372
C40: 678 | D40: 18 | E40: 2 | F40: =(D40-E40)*E40*0.02504 -> 0.80128 | G40: 1 | H40: =CONCATENATE(D40,E40) -> 182 | I40: 2.96 | J40: 2.05 | K40: 2.45 | L40: =I40+J40 -> 5.01 | M40: =I40+K40 -> 5.41 | O40: =((G40*(1-$O$2)+I40+$O$3)*F40*$O$7)*$AB$11 -> 2.7323648 | P40: =((G40*(1-$P$2)+I40+J40+$P$3)*F40*$O$7)*$AB$11 -> 4.3749888 | Q40: =((G40*(1-$Q$2)+I40+K40+$Q$3)*F40*$O$7)*$AB$11 -> 4.6955008 | R40: 0.7128 | S40: =O40+R40*$AB$11 -> 3.4451648 | T40: =P40+R40*$AB$11 -> 5.0877888 | U40: =Q40+R40*$AB$11 -> 5.4083008 | V40: 1.2474 | W40: =O40+V40*$AB$11 -> 3.9797648 | X40: =P40+V40*$AB$11 -> 5.6223888 | Y40: =Q40+V40*$AB$11 -> 5.9429008 | Z40: =F40*C40 -> 543.26784
...

Sheet MARCEGAGLIA
A1: Marcegaglia Divisione Inox | L1: PRICE LIST 2013 ( Ed. 11 / 03 / 2013 )
A2: DISCOUNT | K2: 27 | P2: CORROSION
K3: EN 4301 EN 4307 | L3: EN 4541 | M3: EN 4404 EN 4571
AC4: Cross Rate | AD4: 41334
A5: Alloy Surcharge €/KG | K5: 2.5 | L5: 0 | M5: 3.7
A6: extra 1 €/KG | K6: 0 | AC6: €ur | AD6: 1
A7: extra 2 €/KG | K7: 0 | AC7: GBP | AD7: 0.863
A8: extra 3 €/KG | K8: 0 | AC8: USD | AD8: 1.308
A9: extra percentage | K9: 1 | R9: DAIRY ITEMS - COLD FINISHED 2B
A10: Currency | K10: eur
K11: Not Annealed Mill Finish | P11: POLISHED G.240/320 | X11: MIRROR POLISHED
K12: €ur / mtr | P12: €ur / mtr | X12: €ur / mtr
A13: Dimension | D13: CRUDO EUR/KG | G13: CRUDO EUR/MTR PIENO | K13: 1.4301 1.4307 | L13: 1.4541 | M13: 1.4404 1.4571 | P13: 1.4301 1.4307 | Q13: 1.4306 1.4541 | R13: 1.4404 1.4571 | X13: 1.4301 1.4307 | Y13: 1.4306 1.4541 | Z13: 1.4404 1.4571 | AC13: IN USO | AD13: =VLOOKUP(K10,$AC$2:$AD$9,2) -> 1
A14: Ø Diam. | B14: Thk. | C14: kg/mt | D14: 304 | E14: extra 321 | F14: extra 316 | G14: 304 | H14: extra 321 | I14: extra 316 | K14: 304 / 304 L | L14: 321 | M14: 316 L / Ti | N14: sat | P14: 304 / 304 L | Q14: 321 | R14: 316 L / Ti | V14: pol | X14: 304 / 304 L | Y14: 321 | Z14: 316 L / Ti
A15: 6 | B15: 1 | C15: =(A15-B15)*B15*0.02504 -> 0.1252 | D15: 5.6191667 | E15: 0.25 | F15: 0.45 | G15: =D15*C15 -> 0.70351967 | H15: =+E15*C15 -> 0.0313 | I15: =+F15*C15 -> 0.05634 | K15: =(((G15-G15*$K$2/100)+0.35*C15+($K$5*C15)+($K$6*C15)+($K$7*C15)+($K$8*C15))*$K$9)*$AD$13 -> 0.87038936 | L15: =(((G15-G15*$K$2/100+H15)+0.35*C15+($L$5*C15)+($K$6*C15)+($K$7*C15)+($K$8*C15))*$K$9)*$AD$13 -> 0.58868936 | M15: =(((G15-G15*$K$2/100+I15)+0.35*C15+($M$5*C15)+($K$6*C15)+($K$7*C15)+($K$8*C15))*$K$9)*$AD$13 -> 1.0769694 | AA15: 1200
A16: 8 | B16: 1 | C16: =(A16-B16)*B16*0.02504 -> 0.17528 | D16: 4.3816667 | E16: 0.25 | F16: 0.45 | G16: =D16*C16 -> 0.76801853 | H16: =+E16*C16 -> 0.04382 | I16: =+F16*C16 -> 0.078876 | K16: =(((G16-G16*$K$2/100)+0.35*C16+($K$5*C16)+($K$6*C16)+($K$7*C16)+($K$8*C16))*$K$9)*$AD$13 -> 1.0602015 | L16: =(((G16-G16*$K$2/100+H16)+0.35*C16+($L$5*C16)+($K$6*C16)+($K$7*C16)+($K$8*C16))*$K$9)*$AD$13 -> 0.66582153 | M16: =(((G16-G16*$K$2/100+I16)+0.35*C16+($M$5*C16)+($K$6*C16)+($K$7*C16)+($K$8*C16))*$K$9)*$AD$13 -> 1.3494135 | AA16: 1302
A17: 10 | B17: 1 | C17: =(A17-B17)*B17*0.02504 -> 0.22536 | D17: 3.6922024 | E17: 0.25 | F17: 0.45 | G17: =D17*C17 -> 0.83207473 | H17: =+E17*C17 -> 0.05634 | I17: =+F17*C17 -> 0.101412 | K17: =(((G17-G17*$K$2/100)+0.35*C17+($K$5*C17)+($K$6*C17)+($K$7*C17)+($K$8*C17))*$K$9)*$AD$13 -> 1.2496906 | L17: =(((G17-G17*$K$2/100+H17)+0.35*C17+($L$5*C17)+($K$6*C17)+($K$7*C17)+($K$8*C17))*$K$9)*$AD$13 -> 0.74263055 | M17: =(((G17-G17*$K$2/100+I17)+0.35*C17+($M$5*C17)+($K$6*C17)+($K$7*C17)+($K$8*C17))*$K$9)*$AD$13 -> 1.6215346 | AA17: 1302
A18: 10 | B18: 1.5 | C18: =(A18-B18)*B18*0.02504 -> 0.31926 | D18: 3.8754167 | E18: 0.25 | F18: 0.45 | G18: =D18*C18 -> 1.2372655 | H18: =+E18*C18 -> 0.079815 | I18: =+F18*C18 -> 0.143667 | K18: =(((G18-G18*$K$2/100)+0.35*C18+($K$5*C18)+($K$6*C18)+($K$7*C18)+($K$8*C18))*$K$9)*$AD$13 -> 1.8130948 | L18: =(((G18-G18*$K$2/100+H18)+0.35*C18+($L$5*C18)+($K$6*C18)+($K$7*C18)+($K$8*C18))*$K$9)*$AD$13 -> 1.0947598 | M18: =(((G18-G18*$K$2/100+I18)+0.35*C18+($M$5*C18)+($K$6*C18)+($K$7*C18)+($K$8*C18))*$K$9)*$AD$13 -> 2.3398738 | AA18: 1302
A19: 12 | B19: 1 | C19: =(A19-B19)*B19*0.02504 -> 0.27544 | D19: 3.6320833 | E19: 0.25 | F19: 0.45 | G19: =D19*C19 -> 1.000421 | H19: =+E19*C19 -> 0.06886 | I19: =+F19*C19 -> 0.123948 | K19: =(((G19-G19*$K$2/100)+0.35*C19+($K$5*C19)+($K$6*C19)+($K$7*C19)+($K$8*C19))*$K$9)*$AD$13 -> 1.5153114 | L19: =(((G19-G19*$K$2/100+H19)+0.35*C19+($L$5*C19)+($K$6*C19)+($K$7*C19)+($K$8*C19))*$K$9)*$AD$13 -> 0.89557135 | M19: =(((G19-G19*$K$2/100+I19)+0.35*C19+($M$5*C19)+($K$6*C19)+($K$7*C19)+($K$8*C19))*$K$9)*$AD$13 -> 1.9697874 | N19: 0.36151983 | P19: =K19+N19*$AD$13 -> 1.8768312 | Q19: =L19+N19*$AD$13 -> 1.2570912 | R19: =M19+N19*$AD$13 -> 2.3313072 | V19: 0.61959334 | AA19: 1626
A20: 12 | B20: 1.5 | C20: =(A20-B20)*B20*0.02504 -> 0.39438 | D20: 3.7980655 | E20: 0.25 | F20: 0.45 | G20: =D20*C20 -> 1.4978811 | H20: =+E20*C20 -> 0.098595 | I20: =+F20*C20 -> 0.177471 | K20: =(((G20-G20*$K$2/100)+0.35*C20+($K$5*C20)+($K$6*C20)+($K$7*C20)+($K$8*C20))*$K$9)*$AD$13 -> 2.2174362 | L20: =(((G20-G20*$K$2/100+H20)+0.35*C20+($L$5*C20)+($K$6*C20)+($K$7*C20)+($K$8*C20))*$K$9)*$AD$13 -> 1.3300812 | M20: =(((G20-G20*$K$2/100+I20)+0.35*C20+($M$5*C20)+($K$6*C20)+($K$7*C20)+($K$8*C20))*$K$9)*$AD$13 -> 2.8681632 | N20: 0.36151983 | P20: =K20+N20*$AD$13 -> 2.578956 | Q20: =L20+N20*$AD$13 -> 1.691601 | R20: =M20+N20*$AD$13 -> 3.229683 | V20: 0.61959334 | X20: =K20+V20*$AD$13 -> 2.8370295 | Y20: =L20+V20*$AD$13 -> 1.9496745 | Z20: =M20+V20*$AD$13 -> 3.4877565 | AA20: 1626
A21: 13 | B21: 1 | C21: =(A21-B21)*B21*0.02504 -> 0.30048 | D21: 3.6038095 | E21: 0.25 | F21: 0.45 | G21: =D21*C21 -> 1.0828727 | H21: =+E21*C21 -> 0.07512 | I21: =+F21*C21 -> 0.135216 | K21: =(((G21-G21*$K$2/100)+0.35*C21+($K$5*C21)+($K$6*C21)+($K$7*C21)+($K$8*C21))*$K$9)*$AD$13 -> 1.6468651 | L21: =(((G21-G21*$K$2/100+H21)+0.35*C21+($L$5*C21)+($K$6*C21)+($K$7*C21)+($K$8*C21))*$K$9)*$AD$13 -> 0.97078506 | M21: =(((G21-G21*$K$2/100+I21)+0.35*C21+($M$5*C21)+($K$6*C21)+($K$7*C21)+($K$8*C21))*$K$9)*$AD$13 -> 2.1426571 | N21: 0.36151983 | P21: =K21+N21*$AD$13 -> 2.0083849 | Q21: =L21+N21*$AD$13 -> 1.3323049 | R21: =M21+N21*$AD$13 -> 2.5041769 | V21: 0.61959334 | X21: =K21+V21*$AD$13 -> 2.2664584 | Y21: =L21+V21*$AD$13 -> 1.5903784 | Z21: =M21+V21*$AD$13 -> 2.7622504 | AA21: 1626
A22: 14 | B22: 1 | C22: =(A22-B22)*B22*0.02504 -> 0.32552 | D22: 2.9850595 | E22: 0.25 | F22: 0.45 | G22: =D22*C22 -> 0.97169658 | H22: =+E22*C22 -> 0.08138 | I22: =+F22*C22 -> 0.146484 | K22: =(((G22-G22*$K$2/100)+0.35*C22+($K$5*C22)+($K$6*C22)+($K$7*C22)+($K$8*C22))*$K$9)*$AD$13 -> 1.6370705 | L22: =(((G22-G22*$K$2/100+H22)+0.35*C22+($L$5*C22)+($K$6*C22)+($K$7*C22)+($K$8*C22))*$K$9)*$AD$13 -> 0.9046505 | M22: =(((G22-G22*$K$2/100+I22)+0.35*C22+($M$5*C22)+($K$6*C22)+($K$7*C22)+($K$8*C22))*$K$9)*$AD$13 -> 2.1741785 | N22: 0.36151983 | P22: =K22+N22*$AD$13 -> 1.9985903 | Q22: =L22+N22*$AD$13 -> 1.2661703 | R22: =M22+N22*$AD$13 -> 2.5356983 | V22: 0.61959334 | X22: =K22+V22*$AD$13 -> 2.2566638 | Y22: =L22+V22*$AD$13 -> 1.5242438 | Z22: =M22+V22*$AD$13 -> 2.7937718 | AA22: 1626
A23: 14 | B23: 1.5 | C23: =(A23-B23)*B23*0.02504 -> 0.4695 | D23: 3.0999702 | E23: 0.25 | F23: 0.45 | G23: =D23*C23 -> 1.455436 | H23: =+E23*C23 -> 0.117375 | I23: =+F23*C23 -> 0.211275 | K23: =(((G23-G23*$K$2/100)+0.35*C23+($K$5*C23)+($K$6*C23)+($K$7*C23)+($K$8*C23))*$K$9)*$AD$13 -> 2.4005433 | L23: =(((G23-G23*$K$2/100+H23)+0.35*C23+($L$5*C23)+($K$6*C23)+($K$7*C23)+($K$8*C23))*$K$9)*$AD$13 -> 1.3441683 | M23: =(((G23-G23*$K$2/100+I23)+0.35*C23+($M$5*C23)+($K$6*C23)+($K$7*C23)+($K$8*C23))*$K$9)*$AD$13 -> 3.1752183 | N23: 0.36151983 | P23: =K23+N23*$AD$13 -> 2.7620631 | Q23: =L23+N23*$AD$13 -> 1.7056881 | R23: =M23+N23*$AD$13 -> 3.5367381 | V23: 0.61959334 | X23: =K23+V23*$AD$13 -> 3.0201366 | Y23: =L23+V23*$AD$13 -> 1.9637616 | Z23: =M23+V23*$AD$13 -> 3.7948116 | AA23: 1626
A24: 14 | B24: 2 | C24: =(A24-B24)*B24*0.02504 -> 0.60096 | D24: 3.1559524 | E24: 0.25 | F24: 0.55 | G24: =D24*C24 -> 1.8966011 | H24: =+E24*C24 -> 0.15024 | I24: =+F24*C24 -> 0.330528 | K24: =(((G24-G24*$K$2/100)+0.35*C24+($K$5*C24)+($K$6*C24)+($K$7*C24)+($K$8*C24))*$K$9)*$AD$13 -> 3.0972548 | L24: =(((G24-G24*$K$2/100+H24)+0.35*C24+($L$5*C24)+($K$6*C24)+($K$7*C24)+($K$8*C24))*$K$9)*$AD$13 -> 1.7450948 | M24: =(((G24-G24*$K$2/100+I24)+0.35*C24+($M$5*C24)+($K$6*C24)+($K$7*C24)+($K$8*C24))*$K$9)*$AD$13 -> 4.1489348 | N24: 0.36151983 | P24: =K24+N24*$AD$13 -> 3.4587747 | Q24: =L24+N24*$AD$13 -> 2.1066147 | R24: =M24+N24*$AD$13 -> 4.5104547 | V24: 0.61959334 | X24: =K24+V24*$AD$13 -> 3.7168482 | Y24: =L24+V24*$AD$13 -> 2.3646882 | Z24: =M24+V24*$AD$13 -> 4.7685282 | AA24: 1014
